Workbook

Sheet Resumo
B1: Valuation - CSN (CSNA3)
B2: Data-base 2026-06-30. Dados públicos da CVM e da B3. R$ milhões, salvo indicação.
B3: Estudo acadêmico e de portfólio. Não é recomendação de compra ou venda. O resultado depende das premissas da aba Premissas, que nesta versão são uma proposta automática ainda não revisada.
B5: Resultado no cenário em uso | D5: Valor
B6: Cenário | D6: ='Premissas'!D4
B7: Preço justo por ação (DCF) | D7: ='DCF'!$D$30
B8: Preço de mercado | D8: ='DCF'!D31
B9: Diferença para o mercado | D9: ='DCF'!$D$32
B10: Valor da empresa (EV) | D10: ='DCF'!$D$23
B11: Valor do acionista | D11: ='DCF'!$D$28
B12: WACC | D12: ='DCF'!D14
B13: Custo do capital próprio (Ke) | D13: ='DCF'!D40
B14: Crescimento na perpetuidade | D14: ='DCF'!D15
B15: Peso do valor terminal | D15: ='DCF'!D33
B16: Preço pelo fluxo do acionista (FCFE) | D16: ='DCF'!D44
B18: Como ler a planilha | D18: Aba
B19: Entradas do modelo e seletor de cenário. Comece por aqui. | D19: Premissas
B20: DRE, balanço e fluxo de caixa da CVM, com indicadores. | D20: Histórico
B21: Receita, custos, capex, depreciação, giro e as três demonstrações ligadas. | D21: Projeção
B22: CAPM e custo médio ponderado de capital. | D22: WACC
B23: FCFF e FCFE descontados, valor da empresa, valor do acionista, sensibilidade. | D23: DCF
B24: EV/EBITDA, P/L e P/VP contra as comparáveis. | D24: Múltiplos
B25: Entradas e saídas de caixa e comparativo pessimista, base e otimista. | D25: Cenários

Sheet Premissas
B1: Premissas - CSN (CSNA3)
B2: Células azuis em fundo amarelo são entradas: troque e a planilha inteira recalcula. PROPOSTA AUTOMÁTICA, AINDA NÃO APROVADA
L3: Cenários
B4: Cenário em uso | D4: Base | L4: Pessimista
B5: Número do cenário (1 pessimista, 2 base, 3 otimista) | D5: =MATCH(D4,L4:L6,0) | L5: Base
L6: Otimista
B7: Cenário base (editável) | D7: 2026E | E7: 2027E | F7: 2028E | G7: 2029E | H7: 2030E | I7: De onde veio
B8: Crescimento do volume vendido | D8: 0 | E8: 0 | F8: 0 | G8: 0 | H8: 0 | I8: Volume constante. A CVM não publica toneladas: usar o guidance da empresa.
B9: Variação do preço médio de venda | D9: 0.0069 | E9: 0.043 | F9: 0.038 | G9: 0.0351 | H9: 0.035 | I9: 2026: receita dos últimos 12 meses (LTM 2T26) sobre 2025. 2027 em diante: IPCA esperado no Focus (preço constante em termos reais).
B10: Inflação dos custos e despesas | D10: -0.0042 | E10: 0.043 | F10: 0.038 | G10: 0.0351 | H10: 0.035 | I10: 2026: custo caixa dos últimos 12 meses sobre 2025. 2027 em diante: IPCA esperado no Focus.
B11: Outras receitas/despesas operacionais (% da receita) | D11: -0.0767 | E11: -0.0691 | F11: -0.0616 | G11: -0.0541 | H11: -0.0465 | I11: Do nível dos últimos 12 meses até a mediana de 2021-2025.
B12: Equivalência patrimonial (R$ milhões) | D12: 351.131 | E12: 351.131 | F12: 351.131 | G12: 351.131 | H12: 351.131 | I12: Mediana de 2021-2025, mantida.
B13: Investimento - capex (% da receita) | D13: 0.1326 | E13: 0.1237 | F13: 0.1148 | G13: 0.1059 | H13: 0.097 | I13: Do nível dos últimos 12 meses até a mediana de 2021-2025.
B14: Depreciação (% do ativo fixo inicial) | D14: 0.0983 | E14: 0.0983 | F14: 0.0983 | G14: 0.0983 | H14: 0.0983 | I14: Mediana de 2021-2025, mantida.
B15: Prazo médio de recebimento (dias) | D15: 19.5303 | E15: 19.5303 | F15: 19.5303 | G15: 19.5303 | H15: 19.5303 | I15: Prazo de 2025, mantido.
B16: Prazo médio de estoque (dias) | D16: 135.0709 | E16: 135.0709 | F16: 135.0709 | G16: 135.0709 | H16: 135.0709 | I16: Prazo de 2025, mantido.
B17: Prazo médio de pagamento (dias) | D17: 92.5353 | E17: 92.5353 | F17: 92.5353 | G17: 92.5353 | H17: 92.5353 | I17: Prazo de 2025, mantido.
B18: Captação líquida de dívida (R$ milhões) | D18: 0 | E18: 0 | F18: 0 | G18: 0 | H18: 0 | I18: Dívida bruta mantida no nível de 2025.
B20: Choque dos cenários (soma ao cenário base) | D20: 2026E | E20: 2027E | F20: 2028E | G20: 2029E | H20: 2030E | I20: Choque de 5% no preço em 2027, mantido depois. Ilustrativo.
B21: Crescimento do volume vendido - pessimista | D21: 0 | E21: 0 | F21: 0 | G21: 0 | H21: 0
B22: Crescimento do volume vendido - otimista | D22: 0 | E22: 0 | F22: 0 | G22: 0 | H22: 0
B23: Variação do preço médio de venda - pessimista | D23: 0 | E23: -0.05 | F23: 0 | G23: 0 | H23: 0
B24: Variação do preço médio de venda - otimista | D24: 0 | E24: 0.05 | F24: 0 | G24: 0 | H24: 0
B25: Inflação dos custos e despesas - pessimista | D25: 0 | E25: 0 | F25: 0 | G25: 0 | H25: 0
B26: Inflação dos custos e despesas - otimista | D26: 0 | E26: 0 | F26: 0 | G26: 0 | H26: 0
B28: Premissas em uso (o que a projeção lê) | D28: 2026E | E28: 2027E | F28: 2028E | G28: 2029E | H28: 2030E
B29: Crescimento do volume vendido | D29: =D8+CHOOSE($D$5,D21,0,D22) | E29: =E8+CHOOSE($D$5,E21,0,E22) | F29: =F8+CHOOSE($D$5,F21,0,F22) | G29: =G8+CHOOSE($D$5,G21,0,G22) | H29: =H8+CHOOSE($D$5,H21,0,H22)
B30: Variação do preço médio de venda | D30: =D9+CHOOSE($D$5,D23,0,D24) | E30: =E9+CHOOSE($D$5,E23,0,E24) | F30: =F9+CHOOSE($D$5,F23,0,F24) | G30: =G9+CHOOSE($D$5,G23,0,G24) | H30: =H9+CHOOSE($D$5,H23,0,H24)
B31: Inflação dos custos e despesas | D31: =D10+CHOOSE($D$5,D25,0,D26) | E31: =E10+CHOOSE($D$5,E25,0,E26) | F31: =F10+CHOOSE($D$5,F25,0,F26) | G31: =G10+CHOOSE($D$5,G25,0,G26) | H31: =H10+CHOOSE($D$5,H25,0,H26)
B32: Outras receitas/despesas operacionais (% da receita) | D32: =D11 | E32: =E11 | F32: =F11 | G32: =G11 | H32: =H11
B33: Equivalência patrimonial (R$ milhões) | D33: =D12 | E33: =E12 | F33: =F12 | G33: =G12 | H33: =H12
B34: Investimento - capex (% da receita) | D34: =D13 | E34: =E13 | F34: =F13 | G34: =G13 | H34: =H13
B35: Depreciação (% do ativo fixo inicial) | D35: =D14 | E35: =E14 | F35: =F14 | G35: =G14 | H35: =H14
B36: Prazo médio de recebimento (dias) | D36: =D15 | E36: =E15 | F36: =F15 | G36: =G15 | H36: =H15
B37: Prazo médio de estoque (dias) | D37: =D16 | E37: =E16 | F37: =F16 | G37: =G16 | H37: =H16
B38: Prazo médio de pagamento (dias) | D38: =D17 | E38: =E17 | F38: =F17 | G38: =G17 | H38: =H17
B39: Captação líquida de dívida (R$ milhões) | D39: =D18 | E39: =E18 | F39: =F18 | G39: =G18 | H39: =H18
B41: Premissas gerais | D41: Valor | I41: De onde veio
B42: Alíquota de IR e CSLL | D42: 0.34 | I42: Alíquota nominal: IRPJ 25% + CSLL 9%.
B43: Custo da dívida antes do imposto (Kd) | D43: 0.1291 | I43: Piso: a taxa do Tesouro prefixado de dez anos, sem spread de crédito. Custo implícito mediano 2023-2025: 14.2%.
...

Sheet Histórico
B1: Histórico - CSN
B2: Fonte: demonstrações consolidadas entregues à CVM (DFP e ITR). LTM = últimos doze meses; o balanço é o do trimestre.
B4: R$ milhões | C4: 2018 | D4: 2019 | E4: 2020 | F4: 2021 | G4: 2022 | H4: 2023 | I4: 2024 | J4: 2025 | K4: LTM 2T26
B5: Demonstração do resultado
B6: Receita líquida | C6: 22968.885 | D6: 25436.417 | E6: 30064.02 | F6: 47912.039 | G6: 44362.12 | H6: 45437.95 | I6: 43687.46 | J6: 44797.946 | K6: 45106.972
B7: Custo dos produtos vendidos | C7: -16105.657 | D7: -17263.264 | E7: -19124.901 | F7: -25837.475 | G7: -31054.016 | H7: -33475.189 | I7: -31990.696 | J7: -32404.221 | K7: -32517.962
B8: Lucro bruto | C8: 6863.228 | D8: 8173.153 | E8: 10939.119 | F8: 22074.564 | G8: 13308.104 | H8: 11962.761 | I8: 11696.764 | J8: 12393.725 | K8: 12589.01
B9: Despesas com vendas | C9: -2263.688 | D9: -2342.805 | E9: -2004.417 | F9: -2372.298 | G9: -2575.818 | H9: -3729.089 | I9: -5453.297 | J9: -5033.148 | K9: -5210.199
B10: Despesas gerais e administrativas | C10: -494.023 | D10: -511.065 | E10: -504.458 | F10: -587.148 | G10: -674.119 | H10: -760.894 | I10: -855.999 | J10: -979.164 | K10: -1009.541
B11: Total de despesas/receitas operacionais | C11: 83.332 | D11: -4631.236 | E11: -5224.682 | F11: -1534.602 | G11: -5666.642 | H11: -6776.012 | I11: -7426.742 | J11: -7577.051 | K11: -9243.594
B12: Equivalência patrimonial | C12: 135.706 | D12: 125.715 | E12: 71.755 | F12: 182.504 | G12: 237.917 | H12: 351.131 | I12: 448.048 | J12: 518.744 | K12: 435.292
B13: EBIT (resultado antes do financeiro e dos tributos) | C13: 6946.56 | D13: 3541.917 | E13: 5714.437 | F13: 20539.962 | G13: 7641.462 | H13: 5186.749 | I13: 4270.022 | J13: 4816.674 | K13: 3345.416
B14: Resultado financeiro | C14: -1495.643 | D14: -2131.184 | E14: -796.311 | F14: -1944.184 | G14: -3515.025 | H14: -4151.382 | I14: -5813.371 | J14: -6496.192 | K14: -5895.433
B15: Lucro antes dos tributos | C15: 5450.917 | D15: 1410.733 | E15: 4918.126 | F15: 18595.778 | G15: 4126.437 | H15: 1035.367 | I15: -1543.349 | J15: -1679.518 | K15: -2550.017
B16: Imposto de renda e CSLL | C16: -250.334 | D16: 833.778 | E16: -625.508 | F16: -5000.157 | G16: -1958.739 | H16: -632.718 | I16: 5.208 | J16: 172.792 | K16: 577.159
B17: Lucro líquido consolidado | C17: 5200.583 | D17: 2244.511 | E17: 4292.618 | F17: 13595.621 | G17: 2167.698 | H17: 402.649 | I17: -1538.141 | J17: -1506.726 | K17: -1972.858
B18: Lucro atribuído aos controladores | C18: 5074.136 | D18: 1789.067 | E18: 3794.295 | F18: 12258.628 | G18: 1554.06 | H18: -318.206 | I18: -2591.851 | J18: -2002.374 | K18: -2626.882
B19: Fluxo de caixa
B20: Depreciação, amortização e exaustão | C20: 1273.021 | D20: 1519.331 | E20: 2516.728 | F20: 2212.406 | G20: 2870.231 | H20: 3372.073 | I20: 3786.055 | J20: 4150.475 | K20: 4381.847
B21: Caixa das atividades operacionais | C21: 2208.105 | D21: 4871.879 | E21: 9576.874 | F21: 14793.263 | G21: 2042.793 | H21: 7292.608 | I21: 8650.505 | J21: -973.179 | K21: -245
B22: Investimento em imobilizado e intangível (capex) | C22: 1319.302 | D22: 2215.883 | E22: 1683.839 | F22: 2864.707 | G22: 3352.21 | H22: 4408.119 | I22: 5494.335 | J22: 5935.897 | K22: 5981.896
B23: Dividendos e JCP pagos | C23: 502.002 | D23: 1920.309 | E23: 309.35 | F23: 3290.544 | G23: 3756.738 | H23: 3980.871 | I23: 2535.325 | J23: 695.232 | K23: 905.831
B24: Balanço patrimonial
B25: Caixa e equivalentes | C25: 2248.004 | D25: 1088.955 | E25: 9944.586 | F25: 16646.48 | G25: 11991.356 | H25: 16046.218 | I25: 23310.197 | J25: 14421.022 | K25: 13630.963
B26: Aplicações financeiras | C26: 895.713 | D26: 2633.173 | E26: 3783.362 | F26: 2644.732 | G26: 1456.485 | H26: 1533.004 | I26: 911.378 | J26: 642.715 | K26: 654.791
B27: Contas a receber | C27: 2078.182 | D27: 2047.931 | E27: 2867.352 | F27: 2597.838 | G27: 3233.164 | H27: 3269.764 | I27: 2900.998 | J27: 2397.033 | K27: 2531.565
B28: Estoques | C28: 5039.56 | D28: 5282.75 | E28: 4817.586 | F28: 10943.835 | G28: 11289.229 | H28: 9557.578 | I28: 10439.741 | J28: 10455.5 | K28: 9368.174
B29: Ativo circulante | C29: 12014.483 | D29: 12725.805 | E29: 23386.194 | F29: 34972.354 | G29: 30612.36 | H29: 33077.7 | I29: 39785.693 | J29: 30330.629 | K29: 29739.027
B30: Investimentos em coligadas | C30: 5630.613 | D30: 3584.169 | E30: 3695.78 | F30: 4011.828 | G30: 5219.082 | H30: 5443.131 | I30: 5948.051 | J30: 8292.026 | K30: 8810.278
B31: Imobilizado | C31: 18046.864 | D31: 19700.944 | E31: 19716.223 | F31: 21531.134 | G31: 26370.445 | H31: 27927.458 | I31: 30426.023 | J31: 33919.169 | K31: 34534.185
B32: Intangível | C32: 7253.175 | D32: 7231.781 | E32: 7316.794 | F32: 7657.05 | G32: 10788.054 | H32: 10536.481 | I32: 10438.091 | J32: 11006.125 | K32: 10900.309
B33: Ativo total | C33: 47327.524 | D33: 50869.276 | E33: 63002.149 | F33: 79379.103 | G33: 85354.359 | H33: 91529.72 | I33: 103906.65 | J33: 100575.37 | K33: 100602.03
B34: Fornecedores | C34: 3473.822 | D34: 3012.654 | E34: 4819.539 | F34: 6446.999 | G34: 6596.915 | H34: 7739.52 | I34: 7030.734 | J34: 7162.929 | K34: 7349.91
B35: Empréstimos e financiamentos - curto prazo | C35: 5653.439 | D35: 5125.843 | E35: 4126.453 | F35: 5486.859 | G35: 5193.636 | H35: 7613.367 | I35: 8821.679 | J35: 10428.559 | K35: 8326.693
B36: Passivo circulante | C36: 11438.552 | D36: 11619.957 | E36: 14725.696 | F36: 24541.616 | G36: 22475.119 | H36: 25017.103 | I36: 25116.475 | J36: 28074.399 | K36: 25947.546
... B39: Participação de não controladores | C39: 1310.705 | D39: 1187.388 | E39: 1338.054 | F39: 3059.391 | G39: 2326.577 | H39: 2184.163 | I39: 3187.678 | J39: 2860.291 | K39: 3074.044
B40: Indicadores (fórmulas)
B41: EBITDA (EBIT + depreciação) | C41: =C13+C20 | D41: =D13+D20 | E41: =E13+E20 | F41: =F13+F20 | G41: =G13+G20 | H41: =H13+H20 | I41: =I13+I20 | J41: =J13+J20 | K41: =K13+K20
B42: Custo caixa (custo sem depreciação) | C42: =C7+C20 | D42: =D7+D20 | E42: =E7+E20 | F42: =F7+F20 | G42: =G7+G20 | H42: =H7+H20 | I42: =I7+I20 | J42: =J7+J20 | K42: =K7+K20
B43: Outras receitas/despesas operacionais | C43: =C11-C9-C10-C12 | D43: =D11-D9-D10-D12 | E43: =E11-E9-E10-E12 | F43: =F11-F9-F10-F12 | G43: =G11-G9-G10-G12 | H43: =H11-H9-H10-H12 | I43: =I11-I9-I10-I12 | J43: =J11-J9-J10-J12 | K43: =K11-K9-K10-K12
...

Sheet Projeção
B1: Projeção - CSN
B2: DRE, balanço e fluxo de caixa ligados. Custos e despesas em valor positivo. 2025 é o realizado; os demais anos são fórmulas sobre as premissas.
B4: R$ milhões | C4: 2025 | D4: 2026E | E4: 2027E | F4: 2028E | G4: 2029E | H4: 2030E
B5: Demonstração do resultado
B6: Receita líquida | C6: ='Histórico'!J6 | D6: =C6*(1+'Premissas'!D29)*(1+'Premissas'!D30) | E6: =D6*(1+'Premissas'!E29)*(1+'Premissas'!E30) | F6: =E6*(1+'Premissas'!F29)*(1+'Premissas'!F30) | G6: =F6*(1+'Premissas'!G29)*(1+'Premissas'!G30) | H6: =G6*(1+'Premissas'!H29)*(1+'Premissas'!H30)
B7: (-) Custo caixa (sem depreciação) | C7: =-'Histórico'!J42 | D7: =C7*(1+'Premissas'!D29)*(1+'Premissas'!D31) | E7: =D7*(1+'Premissas'!E29)*(1+'Premissas'!E31) | F7: =E7*(1+'Premissas'!F29)*(1+'Premissas'!F31) | G7: =F7*(1+'Premissas'!G29)*(1+'Premissas'!G31) | H7: =G7*(1+'Premissas'!H29)*(1+'Premissas'!H31)
B8: (-) Despesas com vendas | C8: =-'Histórico'!J9 | D8: =C8*(1+'Premissas'!D29)*(1+'Premissas'!D31) | E8: =D8*(1+'Premissas'!E29)*(1+'Premissas'!E31) | F8: =E8*(1+'Premissas'!F29)*(1+'Premissas'!F31) | G8: =F8*(1+'Premissas'!G29)*(1+'Premissas'!G31) | H8: =G8*(1+'Premissas'!H29)*(1+'Premissas'!H31)
B9: (-) Despesas gerais e administrativas | C9: =-'Histórico'!J10 | D9: =C9*(1+'Premissas'!D31) | E9: =D9*(1+'Premissas'!E31) | F9: =E9*(1+'Premissas'!F31) | G9: =F9*(1+'Premissas'!G31) | H9: =G9*(1+'Premissas'!H31)
B10: (+/-) Outras receitas/despesas operacionais | C10: ='Histórico'!J43 | D10: =D6*'Premissas'!D32 | E10: =E6*'Premissas'!E32 | F10: =F6*'Premissas'!F32 | G10: =G6*'Premissas'!G32 | H10: =H6*'Premissas'!H32
B11: (+/-) Equivalência patrimonial | C11: ='Histórico'!J12 | D11: ='Premissas'!D33 | E11: ='Premissas'!E33 | F11: ='Premissas'!F33 | G11: ='Premissas'!G33 | H11: ='Premissas'!H33
B12: EBITDA | C12: =C6-C7-C8-C9+C10+C11 | D12: =D6-D7-D8-D9+D10+D11 | E12: =E6-E7-E8-E9+E10+E11 | F12: =F6-F7-F8-F9+F10+F11 | G12: =G6-G7-G8-G9+G10+G11 | H12: =H6-H7-H8-H9+H10+H11
B13: (-) Depreciação e amortização | C13: ='Histórico'!J20 | D13: =C23*'Premissas'!D35 | E13: =D23*'Premissas'!E35 | F13: =E23*'Premissas'!F35 | G13: =F23*'Premissas'!G35 | H13: =G23*'Premissas'!H35
B14: EBIT | C14: =C12-C13 | D14: =D12-D13 | E14: =E12-E13 | F14: =F12-F13 | G14: =G12-G13 | H14: =H12-H13
B15: (+/-) Resultado financeiro | C15: ='Histórico'!J14 | D15: =C38*'Premissas'!$D$44-C42*'Premissas'!$D$43 | E15: =D38*'Premissas'!$D$44-D42*'Premissas'!$D$43 | F15: =E38*'Premissas'!$D$44-E42*'Premissas'!$D$43 | G15: =F38*'Premissas'!$D$44-F42*'Premissas'!$D$43 | H15: =G38*'Premissas'!$D$44-G42*'Premissas'!$D$43
B16: Lucro antes dos tributos | C16: =C14+C15 | D16: =D14+D15 | E16: =E14+E15 | F16: =F14+F15 | G16: =G14+G15 | H16: =H14+H15
B17: (-) Imposto de renda e CSLL | C17: =-'Histórico'!J16 | D17: =MAX(0,D16-D11)*'Premissas'!$D$42 | E17: =MAX(0,E16-E11)*'Premissas'!$D$42 | F17: =MAX(0,F16-F11)*'Premissas'!$D$42 | G17: =MAX(0,G16-G11)*'Premissas'!$D$42 | H17: =MAX(0,H16-H11)*'Premissas'!$D$42
B18: Lucro líquido | C18: =C16-C17 | D18: =D16-D17 | E18: =E16-E17 | F18: =F16-F17 | G18: =G16-G17 | H18: =H16-H17
B19: NOPAT (EBIT sem equivalência, após imposto) | C19: =(C14-C11)*(1-'Premissas'!$D$42) | D19: =(D14-D11)*(1-'Premissas'!$D$42) | E19: =(E14-E11)*(1-'Premissas'!$D$42) | F19: =(F14-F11)*(1-'Premissas'!$D$42) | G19: =(G14-G11)*(1-'Premissas'!$D$42) | H19: =(H14-H11)*(1-'Premissas'!$D$42)
B21: Investimento, depreciação e capital de giro
B22: Capex | C22: ='Histórico'!J22 | D22: =D6*'Premissas'!D34 | E22: =E6*'Premissas'!E34 | F22: =F6*'Premissas'!F34 | G22: =G6*'Premissas'!G34 | H22: =H6*'Premissas'!H34
B23: Ativo fixo (imobilizado + intangível) | C23: ='Histórico'!J52 | D23: =C23+D22-D13 | E23: =D23+E22-E13 | F23: =E23+F22-F13 | G23: =F23+G22-G13 | H23: =G23+H22-H13
B24: Contas a receber | C24: ='Histórico'!J27 | D24: =D6*'Premissas'!D36/365 | E24: =E6*'Premissas'!E36/365 | F24: =F6*'Premissas'!F36/365 | G24: =G6*'Premissas'!G36/365 | H24: =H6*'Premissas'!H36/365
B25: Estoques | C25: ='Histórico'!J28 | D25: =D7*'Premissas'!D37/365 | E25: =E7*'Premissas'!E37/365 | F25: =F7*'Premissas'!F37/365 | G25: =G7*'Premissas'!G37/365 | H25: =H7*'Premissas'!H37/365
B26: Fornecedores | C26: ='Histórico'!J34 | D26: =D7*'Premissas'!D38/365 | E26: =E7*'Premissas'!E38/365 | F26: =F7*'Premissas'!F38/365 | G26: =G7*'Premissas'!G38/365 | H26: =H7*'Premissas'!H38/365
B27: Capital de giro | C27: =C24+C25-C26 | D27: =D24+D25-D26 | E27: =E24+E25-E26 | F27: =F24+F25-F26 | G27: =G24+G25-G26 | H27: =H24+H25-H26
B28: Variação do capital de giro (investimento em giro) | D28: =D27-C27 | E28: =E27-D27 | F28: =F27-E27 | G28: =G27-F27 | H28: =H27-G27
B30: Fluxos de caixa livres
B31: FCFF - fluxo de caixa livre da empresa | D31: =D19+D13-D22-D28 | E31: =E19+E13-E22-E28 | F31: =F19+F13-F22-F28 | G31: =G19+G13-G22-G28 | H31: =H19+H13-H22-H28
B32: (+) Captação líquida de dívida | D32: ='Premissas'!D39 | E32: ='Premissas'!E39 | F32: ='Premissas'!F39 | G32: ='Premissas'!G39 | H32: ='Premissas'!H39
B33: FCFE - fluxo de caixa livre do acionista | D33: =D18-D11+D13-D22-D28+D32 | E33: =E18-E11+E13-E22-E28+E32 | F33: =F18-F11+F13-F22-F28+F32 | G33: =G18-G11+G13-G22-G28+G32 | H33: =H18-H11+H13-H22-H28+H32
B34: (-) Dividendos | D34: =MAX(0,D18)*'Premissas'!$D$45 | E34: =MAX(0,E18)*'Premissas'!$D$45 | F34: =MAX(0,F18)*'Premissas'!$D$45 | G34: =MAX(0,G18)*'Premissas'!$D$45 | H34: =MAX(0,H18)*'Premissas'!$D$45
B35: Variação do caixa | D35: =D33-D34 | E35: =E33-E34 | F35: =F33-F34 | G35: =G33-G34 | H35: =H33-H34
B37: Balanço patrimonial resumido
B38: Caixa e aplicações | C38: ='Histórico'!J60 | D38: =C38+D35 | E38: =D38+E35 | F38: =E38+F35 | G38: =F38+G35 | H38: =G38+H35
B39: Investimentos em coligadas | C39: ='Histórico'!J30 | D39: =C39+D11 | E39: =D39+E11 | F39: =E39+F11 | G39: =F39+G11 | H39: =G39+H11
B40: Outros ativos (mantidos) | C40: ='Histórico'!J33-C38-C24-C25-C23-C39 | D40: =C40 | E40: =D40 | F40: =E40 | G40: =F40 | H40: =G40
B41: Ativo total | C41: =C38+C24+C25+C23+C39+C40 | D41: =D38+D24+D25+D23+D39+D40 | E41: =E38+E24+E25+E23+E39+E40 | F41: =F38+F24+F25+F23+F39+F40 | G41: =G38+G24+G25+G23+G39+G40 | H41: =H38+H24+H25+H23+H39+H40
B42: Dívida bruta | C42: ='Histórico'!J61 | D42: =C42+D32 | E42: =D42+E32 | F42: =E42+F32 | G42: =F42+G32 | H42: =G42+H32
B43: Outros passivos (mantidos) | C43: ='Histórico'!J33-C26-C42-C44 | D43: =C43 | E43: =D43 | F43: =E43 | G43: =F43 | H43: =G43
B44: Patrimônio líquido | C44: ='Histórico'!J38 | D44: =C44+D18-D34 | E44: =D44+E18-E34 | F44: =E44+F18-F34 | G44: =F44+G18-G34 | H44: =G44+H18-H34
...

Sheet WACC
B1: Custo de capital
B2: CAPM para o capital próprio; WACC é a média com o custo da dívida depois do imposto.
B4: Capital próprio (CAPM) | D4: Valor | E4: Conta
B5: Juro sem risco (Rf) | D5: ='Premissas'!$D$46
B6: Beta | D6: ='Premissas'!$D$47
B7: Prêmio de risco de mercado | D7: ='Premissas'!$D$48
B8: Prêmio adicional | D8: ='Premissas'!$D$49
B9: Custo do capital próprio (Ke) | D9: =D5+D6*D7+D8 | E9: Ke = Rf + beta x prêmio de mercado + prêmio adicional
B11: Dívida | D11: Valor | E11: Conta
B12: Custo da dívida antes do imposto (Kd) | D12: ='Premissas'!$D$43
B13: Alíquota de IR e CSLL | D13: ='Premissas'!$D$42
B14: Custo da dívida após o imposto | D14: =D12*(1-D13) | E14: Juro é dedutível: Kd x (1 - alíquota)
B16: Média ponderada | D16: Valor | E16: Conta
B17: Peso da dívida | D17: ='Premissas'!$D$50
B18: Peso do capital próprio | D18: =1-D17
B19: WACC | D19: =D9*D18+D14*D17 | E19: WACC = Ke x peso do capital próprio + Kd após imposto x peso da dívida
B21: Referência: estrutura a valor de mercado | D21: Valor | E21: Conta
B22: Valor de mercado (R$ milhões) | D22: ='Premissas'!$D$60
B23: Dívida bruta na data-base (R$ milhões) | D23: ='Histórico'!K61
B24: Peso da dívida a valor de mercado | D24: =D23/(D23+D22) | E24: Compare com o peso usado acima.

Sheet DCF
B1: Fluxo de caixa descontado - CSN
B2: O valor da empresa é a soma dos fluxos de caixa futuros trazidos a valor de hoje.
B4: R$ milhões | D4: 2026E | E4: 2027E | F4: 2028E | G4: 2029E | H4: 2030E
B5: Fluxo da empresa (FCFF), descontado pelo WACC
B6: FCFF | D6: ='Projeção'!D31 | E6: ='Projeção'!E31 | F6: ='Projeção'!F31 | G6: ='Projeção'!G31 | H6: ='Projeção'!H31
B7: Parte do ano que entra no valor | D7: ='Premissas'!$D$57 | E7: 1 | F7: 1 | G7: 1 | H7: 1
B8: Fim do período (anos desde a data-base) | D8: =D7 | E8: =D8+1 | F8: =E8+1 | G8: =F8+1 | H8: =G8+1
B9: Meio do período (quando o caixa entra, em média) | D9: =D8-D7/2 | E9: =E8-E7/2 | F9: =F8-F7/2 | G9: =G8-G7/2 | H9: =H8-H7/2
B10: Fator de desconto | D10: =1/(1+'WACC'!$D$19)^D9 | E10: =1/(1+'WACC'!$D$19)^E9 | F10: =1/(1+'WACC'!$D$19)^F9 | G10: =1/(1+'WACC'!$D$19)^G9 | H10: =1/(1+'WACC'!$D$19)^H9
B11: Valor presente do fluxo | D11: =D6*D7*D10 | E11: =E6*E7*E10 | F11: =F6*F7*F10 | G11: =G6*G7*G10 | H11: =H6*H7*H10
B13: Perpetuidade (Gordon)
B14: WACC | D14: ='WACC'!$D$19
B15: Crescimento na perpetuidade (g) | D15: ='Premissas'!$D$51
B16: FCFF normalizado de 2030 | D16: ='Projeção'!H19+'Projeção'!H13-'Premissas'!$D$52*'Projeção'!H13-'Projeção'!H28 | I16: NOPAT + depreciação - capex de reposição - investimento em giro
B17: Valor terminal no fim do último ano | D17: =D16*(1+D15)/(D14-D15) | I17: FCFF x (1 + g) / (WACC - g)
B18: Valor presente do valor terminal | D18: =D17/(1+D14)^H8
B20: Do valor da empresa ao preço por ação
B21: Valor presente dos fluxos projetados | D21: =SUM($D$11:$H$11)
B22: (+) Valor presente do valor terminal | D22: =D18
B23: Valor da empresa (Enterprise Value) | D23: =D21+D22
B24: (-) Dívida líquida na data-base | D24: ='Histórico'!K62
B25: (-) Participação de não controladores | D25: ='Histórico'!K39
B26: (+) Investimentos em coligadas (valor contábil) | D26: ='Histórico'!K30 | I26: O FCFF não inclui a equivalência; as coligadas entram pelo valor do balanço.
B27: (-) Outros passivos tratados como dívida | D27: ='Premissas'!$D$53
B28: Valor do acionista (Equity Value) | D28: =D23-D24-D25+D26-D27
B29: Ações em circulação (milhões) | D29: ='Premissas'!$D$58
B30: Preço justo por ação | D30: =D28/D29
B31: Preço de mercado | D31: ='Premissas'!$D$59
B32: Diferença para o preço de mercado | D32: =D30/D31-1
B33: Peso do valor terminal no valor da empresa | D33: =D18/D23
B34: EV / EBITDA 2026E implícito | D34: =D23/'Projeção'!D12
B36: Conferência pelo fluxo do acionista (FCFE), descontado pelo Ke
B37: FCFE | D37: ='Projeção'!D33 | E37: ='Projeção'!E33 | F37: ='Projeção'!F33 | G37: ='Projeção'!G33 | H37: ='Projeção'!H33
B38: Fator de desconto | D38: =1/(1+'WACC'!$D$9)^D9 | E38: =1/(1+'WACC'!$D$9)^E9 | F38: =1/(1+'WACC'!$D$9)^F9 | G38: =1/(1+'WACC'!$D$9)^G9 | H38: =1/(1+'WACC'!$D$9)^H9
B39: Valor presente do fluxo | D39: =D37*D7*D38 | E39: =E37*E7*E38 | F39: =F37*F7*F38 | G39: =G37*G7*G38 | H39: =H37*H7*H38
B40: Custo do capital próprio (Ke) | D40: ='WACC'!$D$9
B41: FCFE normalizado de 2030 | D41: ='Projeção'!H18-'Projeção'!H11+'Projeção'!H13-'Premissas'!$D$52*'Projeção'!H13-'Projeção'!H28+'Projeção'!H32
B42: Valor presente do valor terminal | D42: =D41*(1+D15)/(D40-D15)/(1+D40)^H8
B43: Valor do acionista pelo FCFE | D43: =SUM($D$39:$H$39)+D42-D25+D26-D27
B44: Preço por ação pelo FCFE | D44: =D43/D29
...

Sheet Múltiplos
B1: Valuation por múltiplos
B2: Últimos doze meses. A mediana das comparáveis é aplicada aos números da empresa.
B4: Empresa (R$ milhões) | C4: Setor | D4: Preço | E4: Valor de mercado | F4: Dívida líquida | G4: Minoritários | H4: EV | I4: EBITDA | J4: EBIT | K4: Lucro | L4: Patrimônio | M4: EV/EBITDA | N4: EV/EBIT | O4: P/L | P4: P/VP
B5: CSN (CSNA3) | C5: Siderurgia | D5: 6.36 | E5: 8433.9575 | F5: 39079.806 | G5: 3074.044 | H5: =E5+F5+G5 | I5: 7727.263 | J5: 3345.416 | K5: -2626.882 | L5: 12166.332 | M5: =H5/I5 | N5: =H5/J5 | O5: =IF(K5>0,E5/K5,"n.a.") | P5: =E5/L5
B6: Vale (VALE3) | C6: Mineração | D6: 67.64 | E6: 275454.84 | F6: 68192 | G6: 4832 | H6: =E6+F6+G6 | I6: 51933 | J6: 34110 | K6: 10369 | L6: 196635 | M6: =H6/I6 | N6: =H6/J6 | O6: =IF(K6>0,E6/K6,"n.a.") | P6: =E6/L6
B7: Gerdau (GGBR4) | C7: Siderurgia | D7: 24.77 | E7: 46089.048 | F7: 8117.595 | G7: 190.194 | H7: =E7+F7+G7 | I7: 8730.516 | J7: 5034.141 | K7: 2237.081 | L7: 53544.554 | M7: =H7/I7 | N7: =H7/J7 | O7: =IF(K7>0,E7/K7,"n.a.") | P7: =E7/L7
B8: Usiminas (USIM5) | C8: Siderurgia | D8: 7.21 | E8: 8625.6879 | F8: -599.249 | G8: 2893.937 | H8: =E8+F8+G8 | I8: 164.986 | J8: -982.31 | K8: -2320.418 | L8: 20751.154 | M8: =H8/I8 | N8: =H8/J8 | O8: =IF(K8>0,E8/K8,"n.a.") | P8: =E8/L8
B9: CSN Mineração (CMIN3) | C9: Mineração | D9: 5.06 | E9: 27336.323 | F9: 1025.104 | G9: 0.19 | H9: =E9+F9+G9 | I9: 6003.736 | J9: 4642.024 | K9: 2333.063 | L9: 7339.411 | M9: =H9/I9 | N9: =H9/J9 | O9: =IF(K9>0,E9/K9,"n.a.") | P9: =E9/L9
B10: Mediana das comparáveis (sem a empresa) | M10: =MEDIAN(M6:M9) | N10: =MEDIAN(N6:N9) | O10: =MEDIAN(O6:O9) | P10: =MEDIAN(P6:P9)
B12: Preço por ação implícito | C12: R$ / ação | D12: Como
B13: Pelo EV/EBITDA das comparáveis | C13: =IF(I5>0,(M10*I5-F5-G5)/(E5/D5),"n.a.") | D13: Mediana x EBITDA, menos dívida líquida e minoritários
B14: Pelo EV/EBIT das comparáveis | C14: =IF(J5>0,(N10*J5-F5-G5)/(E5/D5),"n.a.") | D14: Mediana x EBIT, menos dívida líquida e minoritários
B15: Pelo P/L das comparáveis | C15: =IF(K5>0,O10*K5/(E5/D5),"n.a.") | D15: Mediana x lucro (não se aplica com prejuízo)
B16: Pelo P/VP das comparáveis | C16: =P10*L5/(E5/D5) | D16: Mediana x patrimônio dos controladores
B17: Pelo fluxo de caixa descontado (aba DCF) | C17: ='DCF'!$D$30 | D17: Para comparar
B18: Preço de mercado | C18: =D5

Sheet Cenários
B1: Cenários e movimento do caixa
B2: Troque o cenário na aba Premissas (célula D4): tudo abaixo e o resto da planilha seguem.
B4: Cenário em uso | D4: ='Premissas'!D4
B6: Entradas e saídas de caixa | D6: 2026E | E6: 2027E | F6: 2028E | G6: 2029E | H6: 2030E
B7: Entradas (cash in)
B8: Caixa gerado pela operação (EBITDA sem equivalência) | D8: ='Projeção'!D12-'Projeção'!D11 | E8: ='Projeção'!E12-'Projeção'!E11 | F8: ='Projeção'!F12-'Projeção'!F11 | G8: ='Projeção'!G12-'Projeção'!G11 | H8: ='Projeção'!H12-'Projeção'!H11
B9: Rendimento do caixa | D9: ='Projeção'!C38*'Premissas'!$D$44 | E9: ='Projeção'!D38*'Premissas'!$D$44 | F9: ='Projeção'!E38*'Premissas'!$D$44 | G9: ='Projeção'!F38*'Premissas'!$D$44 | H9: ='Projeção'!G38*'Premissas'!$D$44
B10: Captação líquida de dívida (se positiva) | D10: =MAX(0,'Projeção'!D32) | E10: =MAX(0,'Projeção'!E32) | F10: =MAX(0,'Projeção'!F32) | G10: =MAX(0,'Projeção'!G32) | H10: =MAX(0,'Projeção'!H32)
B11: Total de entradas | D11: =D8+D9+D10 | E11: =E8+E9+E10 | F11: =F8+F9+F10 | G11: =G8+G9+G10 | H11: =H8+H9+H10
B12: Saídas (cash out)
B13: Imposto de renda e CSLL | D13: ='Projeção'!D17 | E13: ='Projeção'!E17 | F13: ='Projeção'!F17 | G13: ='Projeção'!G17 | H13: ='Projeção'!H17
B14: Capex | D14: ='Projeção'!D22 | E14: ='Projeção'!E22 | F14: ='Projeção'!F22 | G14: ='Projeção'!G22 | H14: ='Projeção'!H22
B15: Investimento em capital de giro | D15: ='Projeção'!D28 | E15: ='Projeção'!E28 | F15: ='Projeção'!F28 | G15: ='Projeção'!G28 | H15: ='Projeção'!H28
B16: Juros da dívida | D16: ='Projeção'!C42*'Premissas'!$D$43 | E16: ='Projeção'!D42*'Premissas'!$D$43 | F16: ='Projeção'!E42*'Premissas'!$D$43 | G16: ='Projeção'!F42*'Premissas'!$D$43 | H16: ='Projeção'!G42*'Premissas'!$D$43
B17: Amortização líquida de dívida (se negativa a captação) | D17: =MAX(0,-'Projeção'!D32) | E17: =MAX(0,-'Projeção'!E32) | F17: =MAX(0,-'Projeção'!F32) | G17: =MAX(0,-'Projeção'!G32) | H17: =MAX(0,-'Projeção'!H32)
B18: Dividendos | D18: ='Projeção'!D34 | E18: ='Projeção'!E34 | F18: ='Projeção'!F34 | G18: ='Projeção'!G34 | H18: ='Projeção'!H34
B19: Total de saídas | D19: =SUM(D13:D18) | E19: =SUM(E13:E18) | F19: =SUM(F13:F18) | G19: =SUM(G13:G18) | H19: =SUM(H13:H18)
B20: Saldo
B21: Entradas - saídas | D21: =D11-D19 | E21: =E11-E19 | F21: =F11-F19 | G21: =G11-G19 | H21: =H11-H19
B22: Caixa no fim do ano | D22: ='Projeção'!D38 | E22: ='Projeção'!E38 | F22: ='Projeção'!F38 | G22: ='Projeção'!G38 | H22: ='Projeção'!H38
B23: Checagem: bate com a variação de caixa da projeção (zero) | D23: =ROUND(D21-'Projeção'!D35,3) | E23: =ROUND(E21-'Projeção'!E35,3) | F23: =ROUND(F21-'Projeção'!F35,3) | G23: =ROUND(G21-'Projeção'!G35,3) | H23: =ROUND(H21-'Projeção'!H35,3)
B26: Comparativo dos cenários (calculado pelo modelo) | D26: Pessimista | E26: Base | F26: Otimista
B27: Preço justo por ação | D27: -8.5857451 | E27: 6.2361183 | F27: 21.057982
B28: Valor da empresa (EV) | D28: 21958.068 | E28: 41613.25 | F28: 61268.433
B29: Valor do acionista | D29: -11385.504 | E29: 8269.6784 | F29: 27924.861
B30: Receita 2030E | D30: 49809.674 | E30: 52317.714 | F30: 54825.754
B31: Margem EBITDA 2030E | D31: 0.16598911 | E31: 0.20374131 | F31: 0.23803951
B32: Caixa no fim de 2030E | D32: -9080.768 | E32: -392.59282 | F32: 6719.2006
B33: Dívida líquida / EBITDA 2030E | D33: 7.4995571 | E33: 5.0019458 | F33: 3.5404508
B35: Preço justo na planilha viva, no cenário em uso | D35: ='DCF'!$D$30
B36: Diferença para o comparativo acima (zero se as premissas não mudaram) | D36: =ROUND(D35-INDEX(D27:F27,'Premissas'!$D$5),2)
