Workbook

Sheet Painel
B1: Valuation de Vale, CSN e Gerdau
B2: Escolha a empresa e o cenário nas células amarelas. Todas as abas recalculam.
B3: Estudo acadêmico e de portfólio, com dados públicos da CVM e da B3. Não é recomendação de compra ou venda. As premissas são uma proposta por regra, ainda não revisada.
X4: Listas (não apagar)
B5: Empresa | D5: Vale (VALE3) | G5: ← clique na célula e escolha na lista | X5: Vale (VALE3) | Y5: =MATCH($D$5,$X$5:$X$7,0) -> 1
B6: Cenário | D6: Moderado | G6: ← clique na célula e escolha na lista | X6: CSN (CSNA3)
X7: Gerdau (GGBR4)
B9: As três variáveis do cenário | C9: Em uso | D9: Pessimista | E9: Moderado | F9: Otimista | G9: Ajuste manual | H9: Partida | X9: Pessimista | Y9: =MATCH($D$6,$X$9:$X$11,0) -> 2
B10: Crescimento da receita, ao ano | C10: =IF(ISNUMBER(G10),MIN(MAX(G10,MIN(D10:F10)),MAX(D10:F10)),CHOOSE(Painel!$Y$9,D10,E10,F10)) -> 0.0378 | D10: =Premissas!$D$7 -> 0 | E10: =Premissas!$E$7 -> 0.0378 | F10: =Premissas!$F$7 -> 0.0683 | H10: =Premissas!$C$7 -> 0.0209 | X10: Moderado
B11: Margem EBITDA em 2030 | C11: =IF(ISNUMBER(G11),MIN(MAX(G11,MIN(D11:F11)),MAX(D11:F11)),CHOOSE(Painel!$Y$9,D11,E11,F11)) -> 0.3936 | D11: =Premissas!$D$8 -> 0.3484 | E11: =Premissas!$E$8 -> 0.3936 | F11: =Premissas!$F$8 -> 0.4542 | H11: =Premissas!$C$8 -> 0.3459 | X11: Otimista
B12: WACC (taxa de desconto) | C12: =IF(ISNUMBER(G12),MIN(MAX(G12,MIN(D12:F12)),MAX(D12:F12)),CHOOSE(Painel!$Y$9,D12,E12,F12)) -> 0.13117675 | D12: =WACC!$D$19+Premissas!$D$9 -> 0.14677675 | E12: =WACC!$D$19+Premissas!$E$9 -> 0.13117675 | F12: =WACC!$D$19+Premissas!$F$9 -> 0.11557675 | H12: =WACC!$D$19 -> 0.13117675
B13: Ajuste manual: digite um valor entre o pessimista e o otimista (ex.: 5%) para testar um meio-termo; deixe vazio para usar o cenário. Partida é o nível de hoje.
B15: Resultado | C15: Valor | D15: O que é
B16: Preço justo por ação | C16: ='Valor justo'!D29 -> 94.944606 | D16: Quanto vale cada ação segundo o modelo, no cenário em uso.
B17: Preço de mercado | C17: ='Valor justo'!D30 -> 67.64 | D17: Último fechamento na B3.
B18: Diferença para o mercado | C18: ='Valor justo'!D31 -> 0.40367543 | D18: Preço justo ÷ preço de mercado − 1.
B19: Valor da empresa (EV) | C19: ='Valor justo'!D22 -> 432425.19 | D19: Valor da operação inteira, em R$ milhões.
B20: Valor do acionista | C20: ='Valor justo'!D27 -> 386649.19 | D20: EV menos dívida líquida e minoritários, mais investimentos.
B21: Peso do valor terminal | C21: ='Valor justo'!D32 -> 0.75656923 | D21: Quanto do valor vem de depois de 2030.
B22: Preço pelo fluxo do acionista (FCFE) | C22: ='Valor justo'!D43 -> 81.70125 | D22: Conferência por outro caminho: deve ficar perto do preço justo.
B24: O caminho do cálculo, começando pelo FCFF | C24: Valor | D24: Onde ver
B25: 1. FCFF de 2027E: o caixa livre da empresa | C25: =FCFF!E13 -> 27056.553 | D25: Aba FCFF
B26: 2. WACC: a taxa que traz o futuro a valor de hoje | C26: =WACC!D22 -> 0.13117675 | D26: Aba WACC
B27: 3. Fluxos de 2026 a 2030, a valor de hoje | C27: ='Valor justo'!D21 -> 105265.59 | D27: Aba Valor justo
B28: 4. Tudo o que vem depois de 2030, a valor de hoje | C28: ='Valor justo'!D18 -> 327159.59 | D28: Aba Valor justo
B29: 5. Valor da empresa (3 + 4) | C29: ='Valor justo'!D22 -> 432425.19 | D29: Aba Valor justo
B30: 6. Valor do acionista (5 − dívida líquida − minoritários + investimentos) | C30: ='Valor justo'!D27 -> 386649.19 | D30: Aba Valor justo
B31: 7. Preço justo (6 ÷ número de ações) | C31: ='Valor justo'!D29 -> 94.944606 | D31: A aba Passo a passo explica cada etapa

Sheet Passo a passo
B1: ="Como o preço justo é calculado - "&Painel!$D$5 -> Como o preço justo é calculado - Vale (VALE3)
B2: O valuation pelo fluxo de caixa da empresa, em sete passos. Os números são os da empresa e do cenário escolhidos no Painel e mudam junto com eles.
B4: 1. Quanto caixa a empresa gera: o FCFF
B5: Tudo começa pelo caixa livre da empresa. Pega-se o lucro da operação depois do imposto (NOPAT), soma-se a depreciação, que é custo mas não sai do caixa, e tira-se o que foi investido em ativos (capex) e em capital de giro.
B6: NOPAT de 2027E (lucro da operação depois do imposto) | C6: =FCFF!E9 -> 43038.827
B7: + Depreciação | C7: =FCFF!E10 -> 17336.088 | D7: não saiu do caixa
B8: − Capex | C8: =FCFF!E11 -> 32791.127 | D8: investimento em ativos
B9: − Variação do capital de giro | C9: =FCFF!E12 -> 527.23446 | D9: dinheiro a mais preso na operação
B10: (=) FCFF de 2027E | C10: =FCFF!E13 -> 27056.553 | D10: a aba FCFF repete a conta para cada ano
B12: 2. Quanto custa o dinheiro: o WACC
B13: Um real daqui a cinco anos vale menos que um real hoje. A taxa que faz essa conta é o WACC: a média entre o retorno que o acionista exige (Ke, pelo CAPM) e o juro da dívida depois do imposto.
B14: Juro sem risco | C14: =WACC!D5 -> 0.1291
B15: + Beta × prêmio de risco de mercado | C15: =WACC!D6*WACC!D7 -> 0.03197034
B16: (=) Ke, o retorno que o acionista exige | C16: =WACC!D9 -> 0.16107034
B17: Custo da dívida depois do imposto | C17: =WACC!D14 -> 0.04719
B18: Peso da dívida | C18: =WACC!D17 -> 0.2625
B19: WACC pelo CAPM (média de Ke e do custo da dívida) | C19: =WACC!D19 -> 0.13117675
B20: (=) WACC em uso (o do cenário ou do ajuste manual) | C20: =WACC!D22 -> 0.13117675 | D20: é a taxa de desconto
B22: 3. Trazer cada fluxo a valor de hoje
B23: Cada FCFF projetado é dividido por (1 + WACC) elevado ao número de anos até ele chegar. De 2026 só entra a parte do ano que ainda não aconteceu.
B24: FCFF de 2027E | C24: ='Valor justo'!E6 -> 27056.553
B25: × Fator de desconto | C25: ='Valor justo'!E10 -> 0.88358746 | D25: 1 ÷ (1 + WACC) elevado aos anos até lá
B26: (=) Valor presente do FCFF de 2027E | C26: ='Valor justo'!E11 -> 23906.831
B27: (=) Soma dos valores presentes de 2026 a 2030 | C27: ='Valor justo'!D21 -> 105265.59
B29: 4. O que vem depois de 2030: a perpetuidade
B30: A empresa não acaba em 2030. Supõe-se que o caixa cresce para sempre a uma taxa g, igual à inflação. A fórmula de Gordon resume todos esses anos em um número, o valor terminal.
B31: FCFF de 2030 ajustado (só repõe o que desgasta) | C31: ='Valor justo'!D16 -> 52965.919
B32: Crescimento para sempre (g) | C32: ='Valor justo'!D15 -> 0.035 | D32: inflação de longo prazo
B33: Valor terminal: FCFF × (1 + g) ÷ (WACC − g) | C33: ='Valor justo'!D17 -> 569989.38
B34: (=) Valor terminal a valor de hoje | C34: ='Valor justo'!D18 -> 327159.59
B36: 5. Valor da empresa (Enterprise Value)
B37: Somando os fluxos descontados e o valor terminal descontado chega-se ao valor da operação inteira, que pertence a credores e acionistas.
B38: Valor presente dos fluxos projetados | C38: ='Valor justo'!D21 -> 105265.59
B39: + Valor presente do valor terminal | C39: ='Valor justo'!D18 -> 327159.59
B40: (=) Valor da empresa (EV) | C40: ='Valor justo'!D22 -> 432425.19
B42: 6. Do valor da empresa ao valor do acionista (Equity Value)
B43: Tira-se o que é dos credores (dívida líquida) e dos sócios das controladas (minoritários) e soma-se o que a empresa tem em participações.
B44: Valor da empresa (EV) | C44: ='Valor justo'!D22 -> 432425.19
B45: − Dívida líquida | C45: ='Valor justo'!D23 -> 68192 | D45: é dos credores
B46: − Minoritários | C46: ='Valor justo'!D24 -> 4832 | D46: é dos sócios das controladas
...

Sheet Demonstrativos
B1: ="Demonstrativos - "&Painel!$D$5 -> Demonstrativos - Vale (VALE3)
B2: DRE, fluxo de caixa e balanço da empresa escolhida no Painel, e os indicadores que saem deles. LTM = últimos doze meses; o balanço dessa coluna é o do trimestre.
B4: R$ milhões | C4: 2018 | D4: 2019 | E4: 2020 | F4: 2021 | G4: 2022 | H4: 2023 | I4: 2024 | J4: 2025 | K4: LTM 2T26 | L4: O que é
B5: Demonstração do resultado
B6: Receita líquida | C6: =INDEX(Dados!C$1:C$112,6+36*(Painel!$Y$5-1)) -> 134483.13 | D6: =INDEX(Dados!D$1:D$112,6+36*(Painel!$Y$5-1)) -> 148639.92 | E6: =INDEX(Dados!E$1:E$112,6+36*(Painel!$Y$5-1)) -> 208528.76 | F6: =INDEX(Dados!F$1:F$112,6+36*(Painel!$Y$5-1)) -> 293524 | G6: =INDEX(Dados!G$1:G$112,6+36*(Painel!$Y$5-1)) -> 226508 | H6: =INDEX(Dados!H$1:H$112,6+36*(Painel!$Y$5-1)) -> 208066 | I6: =INDEX(Dados!I$1:I$112,6+36*(Painel!$Y$5-1)) -> 206005 | J6: =INDEX(Dados!J$1:J$112,6+36*(Painel!$Y$5-1)) -> 213595 | K6: =INDEX(Dados!K$1:K$112,6+36*(Painel!$Y$5-1)) -> 218069 | L6: Tudo o que a empresa vendeu no período, já sem impostos sobre a venda.
B7: Custo dos produtos vendidos | C7: =INDEX(Dados!C$1:C$112,7+36*(Painel!$Y$5-1)) -> -81200.904 | D7: =INDEX(Dados!D$1:D$112,7+36*(Painel!$Y$5-1)) -> -83835.563 | E7: =INDEX(Dados!E$1:E$112,7+36*(Painel!$Y$5-1)) -> -98567.494 | F7: =INDEX(Dados!F$1:F$112,7+36*(Painel!$Y$5-1)) -> -117267 | G7: =INDEX(Dados!G$1:G$112,7+36*(Painel!$Y$5-1)) -> -124195 | H7: =INDEX(Dados!H$1:H$112,7+36*(Painel!$Y$5-1)) -> -120016 | I7: =INDEX(Dados!I$1:I$112,7+36*(Painel!$Y$5-1)) -> -131318 | J7: =INDEX(Dados!J$1:J$112,7+36*(Painel!$Y$5-1)) -> -138887 | K7: =INDEX(Dados!K$1:K$112,7+36*(Painel!$Y$5-1)) -> -141911 | L7: O que custou produzir o que foi vendido, incluindo a depreciação das fábricas e minas.
B8: Lucro bruto | C8: =INDEX(Dados!C$1:C$112,8+36*(Painel!$Y$5-1)) -> 53282.222 | D8: =INDEX(Dados!D$1:D$112,8+36*(Painel!$Y$5-1)) -> 64804.358 | E8: =INDEX(Dados!E$1:E$112,8+36*(Painel!$Y$5-1)) -> 109961.26 | F8: =INDEX(Dados!F$1:F$112,8+36*(Painel!$Y$5-1)) -> 176257 | G8: =INDEX(Dados!G$1:G$112,8+36*(Painel!$Y$5-1)) -> 102313 | H8: =INDEX(Dados!H$1:H$112,8+36*(Painel!$Y$5-1)) -> 88050 | I8: =INDEX(Dados!I$1:I$112,8+36*(Painel!$Y$5-1)) -> 74687 | J8: =INDEX(Dados!J$1:J$112,8+36*(Painel!$Y$5-1)) -> 74708 | K8: =INDEX(Dados!K$1:K$112,8+36*(Painel!$Y$5-1)) -> 76158 | L8: Receita menos custo dos produtos. O que sobra antes das despesas da empresa.
B9: Despesas com vendas | C9: =INDEX(Dados!C$1:C$112,9+36*(Painel!$Y$5-1)) -> 0 | D9: =INDEX(Dados!D$1:D$112,9+36*(Painel!$Y$5-1)) -> 0 | E9: =INDEX(Dados!E$1:E$112,9+36*(Painel!$Y$5-1)) -> 0 | F9: =INDEX(Dados!F$1:F$112,9+36*(Painel!$Y$5-1)) -> 0 | G9: =INDEX(Dados!G$1:G$112,9+36*(Painel!$Y$5-1)) -> 0 | H9: =INDEX(Dados!H$1:H$112,9+36*(Painel!$Y$5-1)) -> 0 | I9: =INDEX(Dados!I$1:I$112,9+36*(Painel!$Y$5-1)) -> 0 | J9: =INDEX(Dados!J$1:J$112,9+36*(Painel!$Y$5-1)) -> 0 | K9: =INDEX(Dados!K$1:K$112,9+36*(Painel!$Y$5-1)) -> 0 | L9: Gastos para vender e entregar: frete, comissões, equipe comercial.
B10: Despesas gerais e administrativas | C10: =INDEX(Dados!C$1:C$112,10+36*(Painel!$Y$5-1)) -> -1916.765 | D10: =INDEX(Dados!D$1:D$112,10+36*(Painel!$Y$5-1)) -> -1924.308 | E10: =INDEX(Dados!E$1:E$112,10+36*(Painel!$Y$5-1)) -> -2856.913 | F10: =INDEX(Dados!F$1:F$112,10+36*(Painel!$Y$5-1)) -> -2601 | G10: =INDEX(Dados!G$1:G$112,10+36*(Painel!$Y$5-1)) -> -2658 | H10: =INDEX(Dados!H$1:H$112,10+36*(Painel!$Y$5-1)) -> -2758 | I10: =INDEX(Dados!I$1:I$112,10+36*(Painel!$Y$5-1)) -> -3397 | J10: =INDEX(Dados!J$1:J$112,10+36*(Painel!$Y$5-1)) -> -3566 | K10: =INDEX(Dados!K$1:K$112,10+36*(Painel!$Y$5-1)) -> -3667 | L10: Gastos da administração: salários do escritório, sistemas, serviços.
B11: Perdas por recuperabilidade de ativos (impairment) | C11: =INDEX(Dados!C$1:C$112,11+36*(Painel!$Y$5-1)) -> -3523.458 | D11: =INDEX(Dados!D$1:D$112,11+36*(Painel!$Y$5-1)) -> -20762.371 | E11: =INDEX(Dados!E$1:E$112,11+36*(Painel!$Y$5-1)) -> -11818.792 | F11: =INDEX(Dados!F$1:F$112,11+36*(Painel!$Y$5-1)) -> -2352 | G11: =INDEX(Dados!G$1:G$112,11+36*(Painel!$Y$5-1)) -> 3833 | H11: =INDEX(Dados!H$1:H$112,11+36*(Painel!$Y$5-1)) -> -1317 | I11: =INDEX(Dados!I$1:I$112,11+36*(Painel!$Y$5-1)) -> 510 | J11: =INDEX(Dados!J$1:J$112,11+36*(Painel!$Y$5-1)) -> -25147 | K11: =INDEX(Dados!K$1:K$112,11+36*(Painel!$Y$5-1)) -> -23490 | L11: Baixa contábil de um ativo que passou a valer menos (impairment). Não sai do caixa.
B12: Total de despesas/receitas operacionais | C12: =INDEX(Dados!C$1:C$112,12+36*(Painel!$Y$5-1)) -> -10106.478 | D12: =INDEX(Dados!D$1:D$112,12+36*(Painel!$Y$5-1)) -> -62564.583 | E12: =INDEX(Dados!E$1:E$112,12+36*(Painel!$Y$5-1)) -> -57893.647 | F12: =INDEX(Dados!F$1:F$112,12+36*(Painel!$Y$5-1)) -> -34922 | G12: =INDEX(Dados!G$1:G$112,12+36*(Painel!$Y$5-1)) -> -11987 | H12: =INDEX(Dados!H$1:H$112,12+36*(Painel!$Y$5-1)) -> -22778 | I12: =INDEX(Dados!I$1:I$112,12+36*(Painel!$Y$5-1)) -> -19228 | J12: =INDEX(Dados!J$1:J$112,12+36*(Painel!$Y$5-1)) -> -42739 | K12: =INDEX(Dados!K$1:K$112,12+36*(Painel!$Y$5-1)) -> -42048 | L12: Soma de todas as despesas e receitas operacionais abaixo do lucro bruto.
B13: Equivalência patrimonial | C13: =INDEX(Dados!C$1:C$112,13+36*(Painel!$Y$5-1)) -> -693.486 | D13: =INDEX(Dados!D$1:D$112,13+36*(Painel!$Y$5-1)) -> -2683.903 | E13: =INDEX(Dados!E$1:E$112,13+36*(Painel!$Y$5-1)) -> -5435.93 | F13: =INDEX(Dados!F$1:F$112,13+36*(Painel!$Y$5-1)) -> -6947 | G13: =INDEX(Dados!G$1:G$112,13+36*(Painel!$Y$5-1)) -> 1616 | H13: =INDEX(Dados!H$1:H$112,13+36*(Painel!$Y$5-1)) -> -5434 | I13: =INDEX(Dados!I$1:I$112,13+36*(Painel!$Y$5-1)) -> -1570 | J13: =INDEX(Dados!J$1:J$112,13+36*(Painel!$Y$5-1)) -> -1170 | K13: =INDEX(Dados!K$1:K$112,13+36*(Painel!$Y$5-1)) -> -453 | L13: Parte do lucro de empresas das quais ela é sócia sem controlar. Não entra no caixa.
B14: EBIT (resultado antes do financeiro e dos tributos) | C14: =INDEX(Dados!C$1:C$112,14+36*(Painel!$Y$5-1)) -> 43175.744 | D14: =INDEX(Dados!D$1:D$112,14+36*(Painel!$Y$5-1)) -> 2239.775 | E14: =INDEX(Dados!E$1:E$112,14+36*(Painel!$Y$5-1)) -> 52067.618 | F14: =INDEX(Dados!F$1:F$112,14+36*(Painel!$Y$5-1)) -> 141335 | G14: =INDEX(Dados!G$1:G$112,14+36*(Painel!$Y$5-1)) -> 90326 | H14: =INDEX(Dados!H$1:H$112,14+36*(Painel!$Y$5-1)) -> 65272 | I14: =INDEX(Dados!I$1:I$112,14+36*(Painel!$Y$5-1)) -> 55459 | J14: =INDEX(Dados!J$1:J$112,14+36*(Painel!$Y$5-1)) -> 31969 | K14: =INDEX(Dados!K$1:K$112,14+36*(Painel!$Y$5-1)) -> 34110 | L14: Lucro da operação, antes de juros e imposto de renda. Lucro bruto menos despesas.
B15: Resultado financeiro | C15: =INDEX(Dados!C$1:C$112,15+36*(Painel!$Y$5-1)) -> -18057.519 | D15: =INDEX(Dados!D$1:D$112,15+36*(Painel!$Y$5-1)) -> -13444.786 | E15: =INDEX(Dados!E$1:E$112,15+36*(Painel!$Y$5-1)) -> -24140.63 | F15: =INDEX(Dados!F$1:F$112,15+36*(Painel!$Y$5-1)) -> 17812 | G15: =INDEX(Dados!G$1:G$112,15+36*(Painel!$Y$5-1)) -> 11378 | H15: =INDEX(Dados!H$1:H$112,15+36*(Painel!$Y$5-1)) -> -9718 | I15: =INDEX(Dados!I$1:I$112,15+36*(Painel!$Y$5-1)) -> -21235 | J15: =INDEX(Dados!J$1:J$112,15+36*(Painel!$Y$5-1)) -> -5276 | K15: =INDEX(Dados!K$1:K$112,15+36*(Painel!$Y$5-1)) -> -9699 | L15: Juros recebidos menos juros pagos, mais variação cambial e derivativos.
B16: Lucro antes dos tributos | C16: =INDEX(Dados!C$1:C$112,16+36*(Painel!$Y$5-1)) -> 25118.225 | D16: =INDEX(Dados!D$1:D$112,16+36*(Painel!$Y$5-1)) -> -11205.011 | E16: =INDEX(Dados!E$1:E$112,16+36*(Painel!$Y$5-1)) -> 27926.988 | F16: =INDEX(Dados!F$1:F$112,16+36*(Painel!$Y$5-1)) -> 159147 | G16: =INDEX(Dados!G$1:G$112,16+36*(Painel!$Y$5-1)) -> 101704 | H16: =INDEX(Dados!H$1:H$112,16+36*(Painel!$Y$5-1)) -> 55554 | I16: =INDEX(Dados!I$1:I$112,16+36*(Painel!$Y$5-1)) -> 34224 | J16: =INDEX(Dados!J$1:J$112,16+36*(Painel!$Y$5-1)) -> 26693 | K16: =INDEX(Dados!K$1:K$112,16+36*(Painel!$Y$5-1)) -> 24411 | L16: Lucro antes do imposto de renda: EBIT mais o resultado financeiro.
B17: Imposto de renda e CSLL | C17: =INDEX(Dados!C$1:C$112,17+36*(Painel!$Y$5-1)) -> 965.98 | D17: =INDEX(Dados!D$1:D$112,17+36*(Painel!$Y$5-1)) -> 2508.971 | E17: =INDEX(Dados!E$1:E$112,17+36*(Painel!$Y$5-1)) -> -3024.647 | F17: =INDEX(Dados!F$1:F$112,17+36*(Painel!$Y$5-1)) -> -25320 | G17: =INDEX(Dados!G$1:G$112,17+36*(Painel!$Y$5-1)) -> -15185 | H17: =INDEX(Dados!H$1:H$112,17+36*(Painel!$Y$5-1)) -> -15000 | I17: =INDEX(Dados!I$1:I$112,17+36*(Painel!$Y$5-1)) -> -3793 | J17: =INDEX(Dados!J$1:J$112,17+36*(Painel!$Y$5-1)) -> -14882 | K17: =INDEX(Dados!K$1:K$112,17+36*(Painel!$Y$5-1)) -> -15720 | L17: Imposto de renda e contribuição social sobre o lucro.
B18: Lucro líquido consolidado | C18: =INDEX(Dados!C$1:C$112,18+36*(Painel!$Y$5-1)) -> 25773.768 | D18: =INDEX(Dados!D$1:D$112,18+36*(Painel!$Y$5-1)) -> -8696.04 | E18: =INDEX(Dados!E$1:E$112,18+36*(Painel!$Y$5-1)) -> 24902.341 | F18: =INDEX(Dados!F$1:F$112,18+36*(Painel!$Y$5-1)) -> 121343 | G18: =INDEX(Dados!G$1:G$112,18+36*(Painel!$Y$5-1)) -> 96337 | H18: =INDEX(Dados!H$1:H$112,18+36*(Painel!$Y$5-1)) -> 40554 | I18: =INDEX(Dados!I$1:I$112,18+36*(Painel!$Y$5-1)) -> 30431 | J18: =INDEX(Dados!J$1:J$112,18+36*(Painel!$Y$5-1)) -> 11811 | K18: =INDEX(Dados!K$1:K$112,18+36*(Painel!$Y$5-1)) -> 8691 | L18: O que sobra para os sócios depois de tudo: custos, despesas, juros e impostos.
B19: Lucro atribuído aos controladores | C19: =INDEX(Dados!C$1:C$112,19+36*(Painel!$Y$5-1)) -> 25656.526 | D19: =INDEX(Dados!D$1:D$112,19+36*(Painel!$Y$5-1)) -> -6671.445 | E19: =INDEX(Dados!E$1:E$112,19+36*(Painel!$Y$5-1)) -> 26712.713 | F19: =INDEX(Dados!F$1:F$112,19+36*(Painel!$Y$5-1)) -> 121228 | G19: =INDEX(Dados!G$1:G$112,19+36*(Painel!$Y$5-1)) -> 95924 | H19: =INDEX(Dados!H$1:H$112,19+36*(Painel!$Y$5-1)) -> 39940 | I19: =INDEX(Dados!I$1:I$112,19+36*(Painel!$Y$5-1)) -> 31592 | J19: =INDEX(Dados!J$1:J$112,19+36*(Painel!$Y$5-1)) -> 13814 | K19: =INDEX(Dados!K$1:K$112,19+36*(Painel!$Y$5-1)) -> 10369 | L19: A parte do lucro que pertence aos acionistas da empresa, sem os sócios de controladas.
B20: Fluxo de caixa
B21: Depreciação, amortização e exaustão | C21: =INDEX(Dados!C$1:C$112,20+36*(Painel!$Y$5-1)) -> 12238.935 | D21: =INDEX(Dados!D$1:D$112,20+36*(Painel!$Y$5-1)) -> 14750.733 | E21: =INDEX(Dados!E$1:E$112,20+36*(Painel!$Y$5-1)) -> 16679.216 | F21: =INDEX(Dados!F$1:F$112,20+36*(Painel!$Y$5-1)) -> 16379 | G21: =INDEX(Dados!G$1:G$112,20+36*(Painel!$Y$5-1)) -> 16386 | H21: =INDEX(Dados!H$1:H$112,20+36*(Painel!$Y$5-1)) -> 15300 | I21: =INDEX(Dados!I$1:I$112,20+36*(Painel!$Y$5-1)) -> 16525 | J21: =INDEX(Dados!J$1:J$112,20+36*(Painel!$Y$5-1)) -> 17306 | K21: =INDEX(Dados!K$1:K$112,20+36*(Painel!$Y$5-1)) -> 17823 | L21: Desgaste contábil de máquinas, minas e prédios no período. É custo, mas não sai do caixa.
B22: Caixa das atividades operacionais | C22: =INDEX(Dados!C$1:C$112,21+36*(Painel!$Y$5-1)) -> 47930.771 | D22: =INDEX(Dados!D$1:D$112,21+36*(Painel!$Y$5-1)) -> 47283.755 | E22: =INDEX(Dados!E$1:E$112,21+36*(Painel!$Y$5-1)) -> 75207.873 | F22: =INDEX(Dados!F$1:F$112,21+36*(Painel!$Y$5-1)) -> 136766 | G22: =INDEX(Dados!G$1:G$112,21+36*(Painel!$Y$5-1)) -> 58201 | H22: =INDEX(Dados!H$1:H$112,21+36*(Painel!$Y$5-1)) -> 65905 | I22: =INDEX(Dados!I$1:I$112,21+36*(Painel!$Y$5-1)) -> 50199 | J22: =INDEX(Dados!J$1:J$112,21+36*(Painel!$Y$5-1)) -> 48765 | K22: =INDEX(Dados!K$1:K$112,21+36*(Painel!$Y$5-1)) -> 50599 | L22: Dinheiro que a operação gerou de verdade no período, depois de impostos e capital de giro.
B23: Investimento em imobilizado e intangível (capex) | C23: =INDEX(Dados!C$1:C$112,22+36*(Painel!$Y$5-1)) -> 13978.533 | D23: =INDEX(Dados!D$1:D$112,22+36*(Painel!$Y$5-1)) -> 14773.97 | E23: =INDEX(Dados!E$1:E$112,22+36*(Painel!$Y$5-1)) -> 22725.636 | F23: =INDEX(Dados!F$1:F$112,22+36*(Painel!$Y$5-1)) -> 27301 | G23: =INDEX(Dados!G$1:G$112,22+36*(Painel!$Y$5-1)) -> 28184 | H23: =INDEX(Dados!H$1:H$112,22+36*(Painel!$Y$5-1)) -> 29446 | I23: =INDEX(Dados!I$1:I$112,22+36*(Painel!$Y$5-1)) -> 35098 | J23: =INDEX(Dados!J$1:J$112,22+36*(Painel!$Y$5-1)) -> 33390 | K23: =INDEX(Dados!K$1:K$112,22+36*(Painel!$Y$5-1)) -> 31848 | L23: Dinheiro investido em máquinas, minas, fábricas e sistemas.
B24: Dividendos e JCP pagos | C24: =INDEX(Dados!C$1:C$112,23+36*(Painel!$Y$5-1)) -> 13050.573 | D24: =INDEX(Dados!D$1:D$112,23+36*(Painel!$Y$5-1)) -> 695.071 | E24: =INDEX(Dados!E$1:E$112,23+36*(Painel!$Y$5-1)) -> 18708.953 | F24: =INDEX(Dados!F$1:F$112,23+36*(Painel!$Y$5-1)) -> 73287 | G24: =INDEX(Dados!G$1:G$112,23+36*(Painel!$Y$5-1)) -> 34157 | H24: =INDEX(Dados!H$1:H$112,23+36*(Painel!$Y$5-1)) -> 27967 | I24: =INDEX(Dados!I$1:I$112,23+36*(Painel!$Y$5-1)) -> 20663 | J24: =INDEX(Dados!J$1:J$112,23+36*(Painel!$Y$5-1)) -> 19971 | K24: =INDEX(Dados!K$1:K$112,23+36*(Painel!$Y$5-1)) -> 23071 | L24: Dinheiro entregue aos acionistas como dividendos e juros sobre capital próprio.
B25: Balanço patrimonial
B26: Caixa e equivalentes | C26: =INDEX(Dados!C$1:C$112,24+36*(Painel!$Y$5-1)) -> 22412.547 | D26: =INDEX(Dados!D$1:D$112,24+36*(Painel!$Y$5-1)) -> 29627.092 | E26: =INDEX(Dados!E$1:E$112,24+36*(Painel!$Y$5-1)) -> 70085.566 | F26: =INDEX(Dados!F$1:F$112,24+36*(Painel!$Y$5-1)) -> 65409 | G26: =INDEX(Dados!G$1:G$112,24+36*(Painel!$Y$5-1)) -> 24711 | H26: =INDEX(Dados!H$1:H$112,24+36*(Painel!$Y$5-1)) -> 17474 | I26: =INDEX(Dados!I$1:I$112,24+36*(Painel!$Y$5-1)) -> 30671 | J26: =INDEX(Dados!J$1:J$112,24+36*(Painel!$Y$5-1)) -> 40563 | K26: =INDEX(Dados!K$1:K$112,24+36*(Painel!$Y$5-1)) -> 28871 | L26: Dinheiro em conta e aplicações de resgate imediato.
B27: Aplicações financeiras | C27: =INDEX(Dados!C$1:C$112,25+36*(Painel!$Y$5-1)) -> 0 | D27: =INDEX(Dados!D$1:D$112,25+36*(Painel!$Y$5-1)) -> 0 | E27: =INDEX(Dados!E$1:E$112,25+36*(Painel!$Y$5-1)) -> 0 | F27: =INDEX(Dados!F$1:F$112,25+36*(Painel!$Y$5-1)) -> 1028 | G27: =INDEX(Dados!G$1:G$112,25+36*(Painel!$Y$5-1)) -> 320 | H27: =INDEX(Dados!H$1:H$112,25+36*(Painel!$Y$5-1)) -> 250 | I27: =INDEX(Dados!I$1:I$112,25+36*(Painel!$Y$5-1)) -> 331 | J27: =INDEX(Dados!J$1:J$112,25+36*(Painel!$Y$5-1)) -> 1066 | K27: =INDEX(Dados!K$1:K$112,25+36*(Painel!$Y$5-1)) -> 971 | L27: Aplicações financeiras de curto prazo.
B28: Contas a receber | C28: =INDEX(Dados!C$1:C$112,26+36*(Painel!$Y$5-1)) -> 11669.973 | D28: =INDEX(Dados!D$1:D$112,26+36*(Painel!$Y$5-1)) -> 11483.278 | E28: =INDEX(Dados!E$1:E$112,26+36*(Painel!$Y$5-1)) -> 27233.885 | F28: =INDEX(Dados!F$1:F$112,26+36*(Painel!$Y$5-1)) -> 21840 | G28: =INDEX(Dados!G$1:G$112,26+36*(Painel!$Y$5-1)) -> 22537 | H28: =INDEX(Dados!H$1:H$112,26+36*(Painel!$Y$5-1)) -> 20317 | I28: =INDEX(Dados!I$1:I$112,26+36*(Painel!$Y$5-1)) -> 14600 | J28: =INDEX(Dados!J$1:J$112,26+36*(Painel!$Y$5-1)) -> 12639 | K28: =INDEX(Dados!K$1:K$112,26+36*(Painel!$Y$5-1)) -> 13534 | L28: Vendas já feitas que os clientes ainda não pagaram.
B29: Estoques | C29: =INDEX(Dados!C$1:C$112,27+36*(Painel!$Y$5-1)) -> 17215.947 | D29: =INDEX(Dados!D$1:D$112,27+36*(Painel!$Y$5-1)) -> 17228.428 | E29: =INDEX(Dados!E$1:E$112,27+36*(Painel!$Y$5-1)) -> 21102.768 | F29: =INDEX(Dados!F$1:F$112,27+36*(Painel!$Y$5-1)) -> 24429 | G29: =INDEX(Dados!G$1:G$112,27+36*(Painel!$Y$5-1)) -> 23386 | H29: =INDEX(Dados!H$1:H$112,27+36*(Painel!$Y$5-1)) -> 22679 | I29: =INDEX(Dados!I$1:I$112,27+36*(Painel!$Y$5-1)) -> 28513 | J29: =INDEX(Dados!J$1:J$112,27+36*(Painel!$Y$5-1)) -> 32666 | K29: =INDEX(Dados!K$1:K$112,27+36*(Painel!$Y$5-1)) -> 32424 | L29: Matéria-prima e produto pronto que ainda não foi vendido.
B30: Ativo circulante | C30: =INDEX(Dados!C$1:C$112,28+36*(Painel!$Y$5-1)) -> 59256.115 | D30: =INDEX(Dados!D$1:D$112,28+36*(Painel!$Y$5-1)) -> 68697.547 | E30: =INDEX(Dados!E$1:E$112,28+36*(Painel!$Y$5-1)) -> 126805.17 | F30: =INDEX(Dados!F$1:F$112,28+36*(Painel!$Y$5-1)) -> 124800 | G30: =INDEX(Dados!G$1:G$112,28+36*(Painel!$Y$5-1)) -> 81009 | H30: =INDEX(Dados!H$1:H$112,28+36*(Painel!$Y$5-1)) -> 90529 | I30: =INDEX(Dados!I$1:I$112,28+36*(Painel!$Y$5-1)) -> 83476 | J30: =INDEX(Dados!J$1:J$112,28+36*(Painel!$Y$5-1)) -> 100645 | K30: =INDEX(Dados!K$1:K$112,28+36*(Painel!$Y$5-1)) -> 91411 | L30: Tudo o que vira dinheiro em até um ano.
B31: Investimentos em coligadas | C31: =INDEX(Dados!C$1:C$112,29+36*(Painel!$Y$5-1)) -> 12495.002 | D31: =INDEX(Dados!D$1:D$112,29+36*(Painel!$Y$5-1)) -> 11277.871 | E31: =INDEX(Dados!E$1:E$112,29+36*(Painel!$Y$5-1)) -> 10556.64 | F31: =INDEX(Dados!F$1:F$112,29+36*(Painel!$Y$5-1)) -> 9771 | G31: =INDEX(Dados!G$1:G$112,29+36*(Painel!$Y$5-1)) -> 9381 | H31: =INDEX(Dados!H$1:H$112,29+36*(Painel!$Y$5-1)) -> 9061 | I31: =INDEX(Dados!I$1:I$112,29+36*(Painel!$Y$5-1)) -> 28158 | J31: =INDEX(Dados!J$1:J$112,29+36*(Painel!$Y$5-1)) -> 27674 | K31: =INDEX(Dados!K$1:K$112,29+36*(Painel!$Y$5-1)) -> 27248 | L31: Participação em outras empresas, pelo valor registrado no balanço.
B32: Imobilizado | C32: =INDEX(Dados!C$1:C$112,30+36*(Painel!$Y$5-1)) -> 187481.5 | D32: =INDEX(Dados!D$1:D$112,30+36*(Painel!$Y$5-1)) -> 187733.15 | E32: =INDEX(Dados!E$1:E$112,30+36*(Painel!$Y$5-1)) -> 213835.75 | F32: =INDEX(Dados!F$1:F$112,30+36*(Painel!$Y$5-1)) -> 233995 | G32: =INDEX(Dados!G$1:G$112,30+36*(Painel!$Y$5-1)) -> 234472 | H32: =INDEX(Dados!H$1:H$112,30+36*(Painel!$Y$5-1)) -> 234302 | I32: =INDEX(Dados!I$1:I$112,30+36*(Painel!$Y$5-1)) -> 247594 | J32: =INDEX(Dados!J$1:J$112,30+36*(Painel!$Y$5-1)) -> 240040 | K32: =INDEX(Dados!K$1:K$112,30+36*(Painel!$Y$5-1)) -> 240188 | L32: Máquinas, minas, fábricas e terrenos, já descontada a depreciação.
B33: Intangível | C33: =INDEX(Dados!C$1:C$112,31+36*(Painel!$Y$5-1)) -> 30850.392 | D33: =INDEX(Dados!D$1:D$112,31+36*(Painel!$Y$5-1)) -> 34256.976 | E33: =INDEX(Dados!E$1:E$112,31+36*(Painel!$Y$5-1)) -> 48308.512 | F33: =INDEX(Dados!F$1:F$112,31+36*(Painel!$Y$5-1)) -> 50287 | G33: =INDEX(Dados!G$1:G$112,31+36*(Painel!$Y$5-1)) -> 53421 | H33: =INDEX(Dados!H$1:H$112,31+36*(Painel!$Y$5-1)) -> 56309 | I33: =INDEX(Dados!I$1:I$112,31+36*(Painel!$Y$5-1)) -> 65105 | J33: =INDEX(Dados!J$1:J$112,31+36*(Painel!$Y$5-1)) -> 49261 | K33: =INDEX(Dados!K$1:K$112,31+36*(Painel!$Y$5-1)) -> 48775 | L33: Direitos, licenças, softwares e ágio de aquisições.
B34: Ativo total | C34: =INDEX(Dados!C$1:C$112,32+36*(Painel!$Y$5-1)) -> 341714.84 | D34: =INDEX(Dados!D$1:D$112,32+36*(Painel!$Y$5-1)) -> 369670.33 | E34: =INDEX(Dados!E$1:E$112,32+36*(Painel!$Y$5-1)) -> 478129.52 | F34: =INDEX(Dados!F$1:F$112,32+36*(Painel!$Y$5-1)) -> 499128 | G34: =INDEX(Dados!G$1:G$112,32+36*(Painel!$Y$5-1)) -> 453387 | H34: =INDEX(Dados!H$1:H$112,32+36*(Painel!$Y$5-1)) -> 455984 | I34: =INDEX(Dados!I$1:I$112,32+36*(Painel!$Y$5-1)) -> 496325 | J34: =INDEX(Dados!J$1:J$112,32+36*(Painel!$Y$5-1)) -> 476094 | K34: =INDEX(Dados!K$1:K$112,32+36*(Painel!$Y$5-1)) -> 462161 | L34: Tudo o que a empresa tem.
B35: Fornecedores | C35: =INDEX(Dados!C$1:C$112,33+36*(Painel!$Y$5-1)) -> 13609.716 | D35: =INDEX(Dados!D$1:D$112,33+36*(Painel!$Y$5-1)) -> 16555.739 | E35: =INDEX(Dados!E$1:E$112,33+36*(Painel!$Y$5-1)) -> 17495.96 | F35: =INDEX(Dados!F$1:F$112,33+36*(Painel!$Y$5-1)) -> 19393 | G35: =INDEX(Dados!G$1:G$112,33+36*(Painel!$Y$5-1)) -> 23278 | H35: =INDEX(Dados!H$1:H$112,33+36*(Painel!$Y$5-1)) -> 25523 | I35: =INDEX(Dados!I$1:I$112,33+36*(Painel!$Y$5-1)) -> 26217 | J35: =INDEX(Dados!J$1:J$112,33+36*(Painel!$Y$5-1)) -> 30621 | K35: =INDEX(Dados!K$1:K$112,33+36*(Painel!$Y$5-1)) -> 32113 | L35: Compras já recebidas que a empresa ainda não pagou.
B36: Empréstimos e financiamentos - curto prazo | C36: =INDEX(Dados!C$1:C$112,34+36*(Painel!$Y$5-1)) -> 3888.522 | D36: =INDEX(Dados!D$1:D$112,34+36*(Painel!$Y$5-1)) -> 5804.801 | E36: =INDEX(Dados!E$1:E$112,34+36*(Painel!$Y$5-1)) -> 5901.375 | F36: =INDEX(Dados!F$1:F$112,34+36*(Painel!$Y$5-1)) -> 6720 | G36: =INDEX(Dados!G$1:G$112,34+36*(Painel!$Y$5-1)) -> 2552 | H36: =INDEX(Dados!H$1:H$112,34+36*(Painel!$Y$5-1)) -> 4940 | I36: =INDEX(Dados!I$1:I$112,34+36*(Painel!$Y$5-1)) -> 7223 | J36: =INDEX(Dados!J$1:J$112,34+36*(Painel!$Y$5-1)) -> 3731 | K36: =INDEX(Dados!K$1:K$112,34+36*(Painel!$Y$5-1)) -> 6534 | L36: Empréstimos e financiamentos que vencem em até um ano.
B37: Passivo circulante | C37: =INDEX(Dados!C$1:C$112,35+36*(Painel!$Y$5-1)) -> 35516.662 | D37: =INDEX(Dados!D$1:D$112,35+36*(Painel!$Y$5-1)) -> 55805.644 | E37: =INDEX(Dados!E$1:E$112,35+36*(Painel!$Y$5-1)) -> 75837.515 | F37: =INDEX(Dados!F$1:F$112,35+36*(Painel!$Y$5-1)) -> 84814 | G37: =INDEX(Dados!G$1:G$112,35+36*(Painel!$Y$5-1)) -> 72478 | H37: =INDEX(Dados!H$1:H$112,35+36*(Painel!$Y$5-1)) -> 70948 | I37: =INDEX(Dados!I$1:I$112,35+36*(Painel!$Y$5-1)) -> 81055 | J37: =INDEX(Dados!J$1:J$112,35+36*(Painel!$Y$5-1)) -> 87320 | K37: =INDEX(Dados!K$1:K$112,35+36*(Painel!$Y$5-1)) -> 76703 | L37: Tudo o que a empresa tem de pagar em até um ano.
B38: Empréstimos e financiamentos - longo prazo | C38: =INDEX(Dados!C$1:C$112,36+36*(Painel!$Y$5-1)) -> 56039.432 | D38: =INDEX(Dados!D$1:D$112,36+36*(Painel!$Y$5-1)) -> 54037.929 | E38: =INDEX(Dados!E$1:E$112,36+36*(Painel!$Y$5-1)) -> 72187.72 | F38: =INDEX(Dados!F$1:F$112,36+36*(Painel!$Y$5-1)) -> 70189 | G38: =INDEX(Dados!G$1:G$112,36+36*(Painel!$Y$5-1)) -> 63778 | H38: =INDEX(Dados!H$1:H$112,36+36*(Painel!$Y$5-1)) -> 62464 | I38: =INDEX(Dados!I$1:I$112,36+36*(Painel!$Y$5-1)) -> 88789 | J38: =INDEX(Dados!J$1:J$112,36+36*(Painel!$Y$5-1)) -> 99726 | K38: =INDEX(Dados!K$1:K$112,36+36*(Painel!$Y$5-1)) -> 91500 | L38: Empréstimos e financiamentos que vencem depois de um ano.
B39: Patrimônio líquido consolidado | C39: =INDEX(Dados!C$1:C$112,37+36*(Painel!$Y$5-1)) -> 173682.18 | D39: =INDEX(Dados!D$1:D$112,37+36*(Painel!$Y$5-1)) -> 157149.35 | E39: =INDEX(Dados!E$1:E$112,37+36*(Painel!$Y$5-1)) -> 180985.98 | F39: =INDEX(Dados!F$1:F$112,37+36*(Painel!$Y$5-1)) -> 197058 | G39: =INDEX(Dados!G$1:G$112,37+36*(Painel!$Y$5-1)) -> 194894 | H39: =INDEX(Dados!H$1:H$112,37+36*(Painel!$Y$5-1)) -> 198325 | I39: =INDEX(Dados!I$1:I$112,37+36*(Painel!$Y$5-1)) -> 213720 | J39: =INDEX(Dados!J$1:J$112,37+36*(Painel!$Y$5-1)) -> 188926 | K39: =INDEX(Dados!K$1:K$112,37+36*(Painel!$Y$5-1)) -> 201467 | L39: O que é dos sócios: ativo total menos todas as dívidas e obrigações.
B40: Participação de não controladores | C40: =INDEX(Dados!C$1:C$112,38+36*(Painel!$Y$5-1)) -> 3279.552 | D40: =INDEX(Dados!D$1:D$112,38+36*(Painel!$Y$5-1)) -> -4330.947 | E40: =INDEX(Dados!E$1:E$112,38+36*(Painel!$Y$5-1)) -> -4798.995 | F40: =INDEX(Dados!F$1:F$112,38+36*(Painel!$Y$5-1)) -> 4655 | G40: =INDEX(Dados!G$1:G$112,38+36*(Painel!$Y$5-1)) -> 7782 | H40: =INDEX(Dados!H$1:H$112,38+36*(Painel!$Y$5-1)) -> 7360 | I40: =INDEX(Dados!I$1:I$112,38+36*(Painel!$Y$5-1)) -> 6948 | J40: =INDEX(Dados!J$1:J$112,38+36*(Painel!$Y$5-1)) -> 4627 | K40: =INDEX(Dados!K$1:K$112,38+36*(Painel!$Y$5-1)) -> 4832 | L40: A parte do patrimônio que pertence a sócios de empresas controladas.
B42: Indicadores (fórmulas) | C42: 2018 | D42: 2019 | E42: 2020 | F42: 2021 | G42: 2022 | H42: 2023 | I42: 2024 | J42: 2025 | K42: LTM 2T26 | L42: O que é e como se calcula
...

Sheet Projeção
B1: ="Projeção - "&Painel!$D$5 -> Projeção - Vale (VALE3)
B2: DRE, investimento, capital de giro e balanço, ligados entre si. Custos e despesas em valor positivo. 2025 é o realizado; os outros anos são fórmulas.
B4: R$ milhões | C4: 2025 | D4: 2026E | E4: 2027E | F4: 2028E | G4: 2029E | H4: 2030E | I4: Como se calcula
B5: Do cenário para cada ano (vem do Painel)
B6: Crescimento da receita | D6: =Premissas!$C$7 -> 0.0209 | E6: =Painel!$C$10 -> 0.0378 | F6: =Painel!$C$10 -> 0.0378 | G6: =Painel!$C$10 -> 0.0378 | H6: =Painel!$C$10 -> 0.0378 | I6: 2026 repete os últimos doze meses. De 2027 em diante vale o crescimento escolhido no Painel.
B7: Margem EBITDA | D7: =Premissas!$C$8+(Painel!$C$11-Premissas!$C$8)*0/4 -> 0.3459 | E7: =Premissas!$C$8+(Painel!$C$11-Premissas!$C$8)*1/4 -> 0.357825 | F7: =Premissas!$C$8+(Painel!$C$11-Premissas!$C$8)*2/4 -> 0.36975 | G7: =Premissas!$C$8+(Painel!$C$11-Premissas!$C$8)*3/4 -> 0.381675 | H7: =Premissas!$C$8+(Painel!$C$11-Premissas!$C$8)*4/4 -> 0.3936 | I7: Sai da margem dos últimos doze meses em 2026 e chega, em linha reta, à margem escolhida no Painel em 2030.
B9: Demonstração do resultado
B10: Receita líquida | C10: =Demonstrativos!J6 -> 213595 | D10: =C10*(1+D6) -> 218059.14 | E10: =D10*(1+E6) -> 226301.77 | F10: =E10*(1+F6) -> 234855.98 | G10: =F10*(1+G6) -> 243733.53 | H10: =G10*(1+H6) -> 252946.66 | I10: Receita do ano anterior × (1 + crescimento).
B11: (-) Custo dos produtos (sem depreciação) | C11: =-Demonstrativos!J45 -> 121581 | D11: =D10-D12+D13-D14 -> 122963.57 | E11: =E10-E12+E13-E14 -> 125311.75 | F11: =F10-F12+F13-F14 -> 127659.5 | G11: =G10-G12+G13-G14 -> 130003.45 | H11: =H10-H12+H13-H14 -> 132339.96 | I11: O que sobra para a margem fechar: receita − despesas + equivalência − EBITDA.
B12: (-) Despesas operacionais (vendas, administrativas e outras) | C12: =-(Demonstrativos!J9+Demonstrativos!J10+Demonstrativos!J46) -> 41569 | D12: =D10*Premissas!$D$12 -> 18098.908 | E12: =E10*Premissas!$E$12 -> 18443.594 | F12: =F10*Premissas!$F$12 -> 18788.478 | G12: =G10*Premissas!$G$12 -> 19133.082 | H12: =H10*Premissas!$H$12 -> 19476.893 | I12: Receita × percentual de despesas operacionais (aba Premissas).
B13: (+/-) Equivalência patrimonial | C13: =Demonstrativos!J13 -> -1170 | D13: =Premissas!$D$13 -> -1570 | E13: =Premissas!$E$13 -> -1570 | F13: =Premissas!$F$13 -> -1570 | G13: =Premissas!$G$13 -> -1570 | H13: =Premissas!$H$13 -> -1570 | I13: Valor fixo da aba Premissas.
B14: EBITDA | C14: =C10-C11-C12+C13 -> 49275 | D14: =D10*D7 -> 75426.655 | E14: =E10*E7 -> 80976.431 | F14: =F10*F7 -> 86837.998 | G14: =G10*G7 -> 93026.996 | H14: =H10*H7 -> 99559.806 | I14: Receita × margem EBITDA do cenário.
B15: (-) Depreciação e amortização | C15: =Demonstrativos!J21 -> 17306 | D15: =C26*Premissas!$D$15 -> 16461.227 | E15: =D26*Premissas!$E$15 -> 17336.088 | F15: =E26*Premissas!$F$15 -> 18215.479 | G15: =F26*Premissas!$G$15 -> 19100.662 | H15: =G26*Premissas!$H$15 -> 19992.86 | I15: Ativo fixo do início do ano × taxa de depreciação (aba Premissas).
B16: EBIT | C16: =C14-C15 -> 31969 | D16: =D14-D15 -> 58965.428 | E16: =E14-E15 -> 63640.344 | F16: =F14-F15 -> 68622.519 | G16: =G14-G15 -> 73926.335 | H16: =H14-H15 -> 79566.946 | I16: EBITDA − depreciação.
B17: (+) Rendimento do caixa | D17: =C38*Premissas!$D$25 -> 3896.4744 | E17: =D38*Premissas!$D$25 -> 3693.0219 | F17: =E38*Premissas!$D$25 -> 3548.3343 | G17: =F38*Premissas!$D$25 -> 3488.3238 | H17: =G38*Premissas!$D$25 -> 3518.9725 | I17: Caixa do início do ano × rendimento do caixa.
B18: (-) Juros da dívida | D18: =C42*Premissas!$D$23 -> 5793.592 | E18: =D42*Premissas!$D$23 -> 5793.592 | F18: =E42*Premissas!$D$23 -> 5793.592 | G18: =F42*Premissas!$D$23 -> 5793.592 | H18: =G42*Premissas!$D$23 -> 5793.592 | I18: Dívida do início do ano × juros pagos sobre a dívida (aba Premissas).
B19: (+/-) Resultado financeiro | C19: =Demonstrativos!J15 -> -5276 | D19: =D17-D18 -> -1897.1176 | E19: =E17-E18 -> -2100.5701 | F19: =F17-F18 -> -2245.2577 | G19: =G17-G18 -> -2305.2682 | H19: =H17-H18 -> -2274.6195 | I19: Rendimento do caixa − juros da dívida.
B20: Lucro antes dos tributos | C20: =C16+C19 -> 26693 | D20: =D16+D19 -> 57068.31 | E20: =E16+E19 -> 61539.773 | F20: =F16+F19 -> 66377.261 | G20: =G16+G19 -> 71621.067 | H20: =H16+H19 -> 77292.326 | I20: EBIT + resultado financeiro.
B21: (-) Imposto de renda e CSLL | C21: =-Demonstrativos!J17 -> 14882 | D21: =MAX(0,D20-D13)*Premissas!$D$22 -> 19937.026 | E21: =MAX(0,E20-E13)*Premissas!$D$22 -> 21457.323 | F21: =MAX(0,F20-F13)*Premissas!$D$22 -> 23102.069 | G21: =MAX(0,G20-G13)*Premissas!$D$22 -> 24884.963 | H21: =MAX(0,H20-H13)*Premissas!$D$22 -> 26813.191 | I21: (Lucro antes do imposto − equivalência) × alíquota. Sem lucro, não há imposto.
B22: Lucro líquido | C22: =C20-C21 -> 11811 | D22: =D20-D21 -> 37131.285 | E22: =E20-E21 -> 40082.45 | F22: =F20-F21 -> 43275.192 | G22: =G20-G21 -> 46736.104 | H22: =H20-H21 -> 50479.135 | I22: Lucro antes do imposto − imposto.
B24: Investimento, depreciação e capital de giro
B25: Capex | C25: =Demonstrativos!J23 -> 33390 | D25: =D10*Premissas!$D$14 -> 31836.634 | E25: =E10*Premissas!$E$14 -> 32791.127 | F25: =F10*Premissas!$F$14 -> 33772.29 | G25: =G10*Premissas!$G$14 -> 34780.775 | H25: =H10*Premissas!$H$14 -> 35791.953 | I25: Receita × percentual de capex (aba Premissas).
B26: Ativo fixo (imobilizado + intangível) | C26: =Demonstrativos!J55 -> 289301 | D26: =C26+D25-D15 -> 304676.41 | E26: =D26+E25-E15 -> 320131.45 | F26: =E26+F25-F15 -> 335688.26 | G26: =F26+G25-G15 -> 351368.37 | H26: =G26+H25-H15 -> 367167.46 | I26: Ativo fixo anterior + capex − depreciação.
B27: Contas a receber | C27: =Demonstrativos!J28 -> 12639 | D27: =D10*Premissas!$D$16/365 -> 12903.127 | E27: =E10*Premissas!$E$16/365 -> 13390.865 | F27: =F10*Premissas!$F$16/365 -> 13897.039 | G27: =G10*Premissas!$G$16/365 -> 14422.348 | H27: =H10*Premissas!$H$16/365 -> 14967.512 | I27: Receita × prazo de recebimento ÷ 365.
B28: Estoques | C28: =Demonstrativos!J29 -> 32666 | D28: =D11*Premissas!$D$17/365 -> 33037.448 | E28: =E11*Premissas!$E$17/365 -> 33668.348 | F28: =F11*Premissas!$F$17/365 -> 34299.135 | G28: =G11*Premissas!$G$17/365 -> 34928.901 | H28: =H11*Premissas!$H$17/365 -> 35556.666 | I28: Custo dos produtos × prazo de estoque ÷ 365.
B29: Fornecedores | C29: =Demonstrativos!J35 -> 30621 | D29: =D11*Premissas!$D$18/365 -> 30969.201 | E29: =E11*Premissas!$E$18/365 -> 31560.604 | F29: =F11*Premissas!$F$18/365 -> 32151.902 | G29: =G11*Premissas!$G$18/365 -> 32742.243 | H29: =H11*Premissas!$H$18/365 -> 33330.708 | I29: Custo dos produtos × prazo de pagamento ÷ 365.
B30: Capital de giro | C30: =C27+C28-C29 -> 14684 | D30: =D27+D28-D29 -> 14971.374 | E30: =E27+E28-E29 -> 15498.608 | F30: =F27+F28-F29 -> 16044.272 | G30: =G27+G28-G29 -> 16609.006 | H30: =H27+H28-H29 -> 17193.47 | I30: Contas a receber + estoques − fornecedores.
B31: Variação do capital de giro (investimento em giro) | D31: =D30-C30 -> 287.37388 | E31: =E30-D30 -> 527.23446 | F31: =F30-E30 -> 545.66395 | G31: =G30-F30 -> 564.73338 | H31: =H30-G30 -> 584.4648 | I31: Capital de giro do ano − o do ano anterior. Positivo consome caixa.
B33: Do lucro ao caixa
B34: (-) Dividendos | D34: =MAX(0,D22)*Premissas!$D$26 -> 25212.142 | E34: =MAX(0,E22)*Premissas!$D$26 -> 27215.984 | F34: =MAX(0,F22)*Premissas!$D$26 -> 29383.855 | G34: =MAX(0,G22)*Premissas!$D$26 -> 31733.815 | H34: =MAX(0,H22)*Premissas!$D$26 -> 34275.333 | I34: Lucro líquido × percentual distribuído (aba Premissas). Sem lucro, não há dividendo.
B35: Variação do caixa (FCFE da aba FCFF menos dividendos) | D35: =FCFF!D22-D34 -> -2173.6383 | E35: =FCFF!E22-E34 -> -1545.8069 | F35: =FCFF!F22-F34 -> -641.1376 | G35: =FCFF!G22-G34 -> 327.4425 | H35: =FCFF!H22-H34 -> 1390.2453 | I35: FCFE − dividendos: o que entra ou sai do caixa no ano.
B37: Balanço patrimonial resumido
B38: Caixa e aplicações | C38: =Demonstrativos!J63 -> 41629 | D38: =C38+D35 -> 39455.362 | E38: =D38+E35 -> 37909.555 | F38: =E38+F35 -> 37268.417 | G38: =F38+G35 -> 37595.86 | H38: =G38+H35 -> 38986.105 | I38: Caixa anterior + variação do caixa. É a conta que fecha o balanço.
B39: Investimentos em coligadas | C39: =Demonstrativos!J31 -> 27674 | D39: =C39+D13 -> 26104 | E39: =D39+E13 -> 24534 | F39: =E39+F13 -> 22964 | G39: =F39+G13 -> 21394 | H39: =G39+H13 -> 19824 | I39: Saldo anterior + equivalência do ano.
B40: Outros ativos (mantidos) | C40: =Demonstrativos!J34-C38-C27-C28-C26-C39 -> 72185 | D40: =C40 -> 72185 | E40: =D40 -> 72185 | F40: =E40 -> 72185 | G40: =F40 -> 72185 | H40: =G40 -> 72185 | I40: Tudo o que o modelo não projeta linha a linha; fica constante.
B41: Ativo total | C41: =C38+C27+C28+C26+C39+C40 -> 476094 | D41: =D38+D27+D28+D26+D39+D40 -> 488361.34 | E41: =E38+E27+E28+E26+E39+E40 -> 501819.21 | F41: =F38+F27+F28+F26+F39+F40 -> 516301.85 | G41: =G38+G27+G28+G26+G39+G40 -> 531894.48 | H41: =H38+H27+H28+H26+H39+H40 -> 548686.75 | I41: Soma de todas as linhas do ativo.
B42: Dívida bruta | C42: =Demonstrativos!J64 -> 103457 | D42: =C42+Premissas!$D$19 -> 103457 | E42: =D42+Premissas!$E$19 -> 103457 | F42: =E42+Premissas!$F$19 -> 103457 | G42: =F42+Premissas!$G$19 -> 103457 | H42: =G42+Premissas!$H$19 -> 103457 | I42: Dívida anterior + captação líquida (aba Premissas).
B43: Outros passivos (mantidos) | C43: =Demonstrativos!J34-C29-C42-C44 -> 153090 | D43: =C43 -> 153090 | E43: =D43 -> 153090 | F43: =E43 -> 153090 | G43: =F43 -> 153090 | H43: =G43 -> 153090 | I43: Tudo o que o modelo não projeta linha a linha; fica constante.
B44: Patrimônio líquido | C44: =Demonstrativos!J39 -> 188926 | D44: =C44+D22-D34 -> 200845.14 | E44: =D44+E22-E34 -> 213711.61 | F44: =E44+F22-F34 -> 227602.95 | G44: =F44+G22-G34 -> 242605.24 | H44: =G44+H22-H34 -> 258809.04 | I44: Patrimônio anterior + lucro líquido − dividendos.
B45: Passivo + patrimônio líquido | C45: =C29+C42+C43+C44 -> 476094 | D45: =D29+D42+D43+D44 -> 488361.34 | E45: =E29+E42+E43+E44 -> 501819.21 | F45: =F29+F42+F43+F44 -> 516301.85 | G45: =G29+G42+G43+G44 -> 531894.48 | H45: =H29+H42+H43+H44 -> 548686.75 | I45: Fornecedores + dívida + outros passivos + patrimônio líquido.
...

Sheet FCFF
B1: ="FCFF e FCFE - "&Painel!$D$5 -> FCFF e FCFE - Vale (VALE3)
B2: O caixa livre de cada ano, que é o ponto de partida do valuation. FCFF é o caixa da empresa inteira; FCFE é a parte do acionista.
B4: R$ milhões | D4: 2026E | E4: 2027E | F4: 2028E | G4: 2029E | H4: 2030E | I4: O que é e como se calcula
B5: FCFF: o caixa livre da empresa, para credores e acionistas
B6: EBIT | D6: =Projeção!D16 -> 58965.428 | E6: =Projeção!E16 -> 63640.344 | F6: =Projeção!F16 -> 68622.519 | G6: =Projeção!G16 -> 73926.335 | H6: =Projeção!H16 -> 79566.946 | I6: Lucro da operação antes de juros e impostos (aba Projeção).
B7: (-) Equivalência patrimonial | D7: =Projeção!D13 -> -1570 | E7: =Projeção!E13 -> -1570 | F7: =Projeção!F13 -> -1570 | G7: =Projeção!G13 -> -1570 | H7: =Projeção!H13 -> -1570 | I7: Sai da conta: é lucro de outras empresas, não entra no caixa desta.
B8: (-) Imposto sobre o lucro da operação | D8: =(D6-D7)*Premissas!$D$22 -> 20582.046 | E8: =(E6-E7)*Premissas!$D$22 -> 22171.517 | F8: =(F6-F7)*Premissas!$D$22 -> 23865.456 | G8: =(G6-G7)*Premissas!$D$22 -> 25668.754 | H8: =(H6-H7)*Premissas!$D$22 -> 27586.562 | I8: (EBIT − equivalência) × alíquota: o imposto que a operação pagaria sem dívida.
B9: (=) NOPAT | D9: =D6-D7-D8 -> 39953.383 | E9: =E6-E7-E8 -> 43038.827 | F9: =F6-F7-F8 -> 46327.062 | G9: =G6-G7-G8 -> 49827.581 | H9: =H6-H7-H8 -> 53550.384 | I9: EBIT − equivalência − imposto: o lucro da operação depois do imposto.
B10: (+) Depreciação e amortização | D10: =Projeção!D15 -> 16461.227 | E10: =Projeção!E15 -> 17336.088 | F10: =Projeção!F15 -> 18215.479 | G10: =Projeção!G15 -> 19100.662 | H10: =Projeção!H15 -> 19992.86 | I10: Volta para a conta: foi descontada no EBIT, mas não saiu do caixa.
B11: (-) Capex | D11: =Projeção!D25 -> 31836.634 | E11: =Projeção!E25 -> 32791.127 | F11: =Projeção!F25 -> 33772.29 | G11: =Projeção!G25 -> 34780.775 | H11: =Projeção!H25 -> 35791.953 | I11: Sai da conta: dinheiro investido em ativos.
B12: (-) Variação do capital de giro | D12: =Projeção!D31 -> 287.37388 | E12: =Projeção!E31 -> 527.23446 | F12: =Projeção!F31 -> 545.66395 | G12: =Projeção!G31 -> 564.73338 | H12: =Projeção!H31 -> 584.4648 | I12: Sai da conta: dinheiro a mais preso em clientes e estoques.
B13: (=) FCFF | D13: =D9+D10-D11-D12 -> 24290.602 | E13: =E9+E10-E11-E12 -> 27056.553 | F13: =F9+F10-F11-F12 -> 30224.588 | G13: =G9+G10-G11-G12 -> 33582.734 | H13: =H9+H10-H11-H12 -> 37166.827 | I13: NOPAT + depreciação − capex − variação do giro. É o caixa livre para credores e acionistas.
B15: FCFE: o caixa livre só do acionista
B16: Lucro líquido | D16: =Projeção!D22 -> 37131.285 | E16: =Projeção!E22 -> 40082.45 | F16: =Projeção!F22 -> 43275.192 | G16: =Projeção!G22 -> 46736.104 | H16: =Projeção!H22 -> 50479.135 | I16: Lucro depois de juros e impostos (aba Projeção).
B17: (-) Equivalência patrimonial | D17: =Projeção!D13 -> -1570 | E17: =Projeção!E13 -> -1570 | F17: =Projeção!F13 -> -1570 | G17: =Projeção!G13 -> -1570 | H17: =Projeção!H13 -> -1570 | I17: Sai da conta: é lucro de outras empresas, não entra no caixa desta.
B18: (+) Depreciação e amortização | D18: =Projeção!D15 -> 16461.227 | E18: =Projeção!E15 -> 17336.088 | F18: =Projeção!F15 -> 18215.479 | G18: =Projeção!G15 -> 19100.662 | H18: =Projeção!H15 -> 19992.86 | I18: Volta para a conta: foi descontada no EBIT, mas não saiu do caixa.
B19: (-) Capex | D19: =Projeção!D25 -> 31836.634 | E19: =Projeção!E25 -> 32791.127 | F19: =Projeção!F25 -> 33772.29 | G19: =Projeção!G25 -> 34780.775 | H19: =Projeção!H25 -> 35791.953 | I19: Sai da conta: dinheiro investido em ativos.
B20: (-) Variação do capital de giro | D20: =Projeção!D31 -> 287.37388 | E20: =Projeção!E31 -> 527.23446 | F20: =Projeção!F31 -> 545.66395 | G20: =Projeção!G31 -> 564.73338 | H20: =Projeção!H31 -> 584.4648 | I20: Sai da conta: dinheiro a mais preso em clientes e estoques.
B21: (+) Captação líquida de dívida | D21: =Premissas!$D$19 -> 0 | E21: =Premissas!$E$19 -> 0 | F21: =Premissas!$F$19 -> 0 | G21: =Premissas!$G$19 -> 0 | H21: =Premissas!$H$19 -> 0 | I21: Dívida nova menos dívida paga no ano.
B22: (=) FCFE | D22: =D16-D17+D18-D19-D20+D21 -> 23038.504 | E22: =E16-E17+E18-E19-E20+E21 -> 25670.177 | F22: =F16-F17+F18-F19-F20+F21 -> 28742.718 | G22: =G16-G17+G18-G19-G20+G21 -> 32061.257 | H22: =H16-H17+H18-H19-H20+H21 -> 35665.578 | I22: Lucro líquido − equivalência + depreciação − capex − variação do giro + captação. É o caixa livre só do acionista.
B24: Fluxo de 2030 ajustado para a perpetuidade
B25: Capex de reposição | D25: =Premissas!$D$33*H10 -> 19992.86 | I25: Depois de 2030 a empresa só repõe o que desgasta: depreciação × múltiplo da aba Premissas.
B26: FCFF normalizado de 2030 | D26: =H9+H10-D25-H12 -> 52965.919 | I26: FCFF de 2030 com o capex de reposição no lugar do capex do ano.
B27: FCFE normalizado de 2030 | D27: =H16-H17+H18-D25-H20+H21 -> 51464.67 | I27: FCFE de 2030 com o capex de reposição no lugar do capex do ano.

Sheet WACC
B1: ="Custo de capital - "&Painel!$D$5 -> Custo de capital - Vale (VALE3)
B2: CAPM para o capital próprio; WACC é a média com o custo da dívida depois do imposto.
B4: Capital próprio (CAPM) | D4: Valor | E4: O que é e como se calcula
B5: Juro sem risco (Rf) | D5: =Premissas!$D$27 -> 0.1291 | E5: O juro de um investimento sem risco de calote: o título do Tesouro prefixado de dez anos.
B6: Beta | D6: =Premissas!$D$28 -> 0.7558 | E6: Quanto a ação costuma andar quando a bolsa anda 1%. Acima de 1, oscila mais que o mercado.
B7: Prêmio de risco de mercado | D7: =Premissas!$D$29 -> 0.0423 | E7: O retorno a mais que o investidor exige para estar em ações em vez de títulos do governo.
B8: Prêmio adicional | D8: =Premissas!$D$30 -> 0 | E8: Prêmio extra por risco próprio da empresa. Zero nesta versão.
B9: Custo do capital próprio (Ke) | D9: =D5+D6*D7+D8 -> 0.16107034 | E9: Ke = juro sem risco + beta × prêmio de mercado + prêmio adicional. É o retorno que o acionista exige.
B11: Dívida | D11: Valor | E11: O que é e como se calcula
B12: Custo da dívida antes do imposto (Kd) | D12: =Premissas!$D$24 -> 0.0715 | E12: O que a dívida custa à empresa, em reais. Vem do custo que ela divulga (aba Premissas).
B13: Alíquota de IR e CSLL | D13: =Premissas!$D$22 -> 0.34 | E13: Alíquota de imposto sobre o lucro.
B14: Custo da dívida após o imposto | D14: =D12*(1-D13) -> 0.04719 | E14: Kd × (1 − alíquota). O juro reduz o imposto a pagar, então a dívida custa menos.
B16: Média ponderada | D16: Valor | E16: O que é e como se calcula
B17: Peso da dívida | D17: =Premissas!$D$31 -> 0.2625 | E17: Quanto do capital da empresa vem de dívida.
B18: Peso do capital próprio | D18: =1-D17 -> 0.7375 | E18: 1 − peso da dívida: quanto do capital vem dos sócios.
B19: WACC pelo CAPM | D19: =D9*D18+D14*D17 -> 0.13117675 | E19: Ke × peso dos sócios + Kd após imposto × peso da dívida. É o custo médio do capital.
B21: Cenário (vem do Painel) | D21: Valor | E21: O que é e como se calcula
B22: WACC em uso | D22: =Painel!$C$12 -> 0.13117675 | E22: A taxa escolhida no Painel. É ela que desconta o FCFF.
B23: Diferença para o CAPM | D23: =D22-D19 -> 0 | E23: WACC em uso − WACC do CAPM: quanto o cenário ou o ajuste manual deslocou a taxa.
B24: Ke em uso | D24: =D9+D23 -> 0.16107034 | E24: Ke + o mesmo ajuste. É a taxa que desconta o FCFE.
B26: Referência: estrutura a valor de mercado | D26: Valor | E26: O que é e como se calcula
B27: Valor de mercado (R$ milhões) | D27: =Premissas!$D$40 -> 275454.84 | E27: Preço da ação × número de ações.
B28: Dívida bruta na data-base (R$ milhões) | D28: =Demonstrativos!K64 -> 98034 | E28: Dívida bruta no último balanço.
B29: Peso da dívida a valor de mercado | D29: =D28/(D28+D27) -> 0.26248174 | E29: Dívida ÷ (dívida + valor de mercado): serve para conferir o peso usado.

Sheet Valor justo
B1: ="Valor justo - "&Painel!$D$5 -> Valor justo - Vale (VALE3)
B2: Os fluxos de caixa trazidos a valor de hoje, o valor da empresa, o valor do acionista e o preço por ação.
B4: R$ milhões | D4: 2026E | E4: 2027E | F4: 2028E | G4: 2029E | H4: 2030E | I4: O que é e como se calcula
B5: Fluxo da empresa (FCFF), descontado pelo WACC
B6: FCFF | D6: =FCFF!D13 -> 24290.602 | E6: =FCFF!E13 -> 27056.553 | F6: =FCFF!F13 -> 30224.588 | G6: =FCFF!G13 -> 33582.734 | H6: =FCFF!H13 -> 37166.827 | I6: O caixa livre de cada ano (aba FCFF).
B7: Parte do ano que entra no valor | D7: =(DATE(2026,12,31)-Premissas!$D$37)/365 -> 0.50410959 | E7: 1 | F7: 1 | G7: 1 | H7: 1 | I7: De 2026 só conta a parte do ano que vem depois do último balanço. Os outros anos contam inteiros.
B8: Fim do período (anos desde a data-base) | D8: =D7 -> 0.50410959 | E8: =D8+1 -> 1.5041096 | F8: =E8+1 -> 2.5041096 | G8: =F8+1 -> 3.5041096 | H8: =G8+1 -> 4.5041096 | I8: Quantos anos faltam, a partir do último balanço, até o fim de cada ano.
B9: Meio do período (quando o caixa entra, em média) | D9: =D8-D7/2 -> 0.25205479 | E9: =E8-E7/2 -> 1.0041096 | F9: =F8-F7/2 -> 2.0041096 | G9: =G8-G7/2 -> 3.0041096 | H9: =H8-H7/2 -> 4.0041096 | I9: O caixa entra ao longo do ano, não no último dia: usa-se o meio do período.
B10: Fator de desconto | D10: =1/(1+WACC!$D$22)^D9 -> 0.96940976 | E10: =1/(1+WACC!$D$22)^E9 -> 0.88358746 | F10: =1/(1+WACC!$D$22)^F9 -> 0.78112236 | G10: =1/(1+WACC!$D$22)^G9 -> 0.69053962 | H10: =1/(1+WACC!$D$22)^H9 -> 0.61046129 | I10: 1 ÷ (1 + WACC) elevado ao número de anos. Quanto vale hoje R$ 1 recebido naquela data.
B11: Valor presente do fluxo | D11: =D6*D7*D10 -> 11870.544 | E11: =E6*E7*E10 -> 23906.831 | F11: =F6*F7*F10 -> 23609.102 | G11: =G6*G7*G10 -> 23190.208 | H11: =H6*H7*H10 -> 22688.909 | I11: FCFF × parte do ano × fator de desconto.
B13: Perpetuidade (Gordon)
B14: WACC | D14: =WACC!$D$22 -> 0.13117675 | I14: A taxa de desconto em uso (aba WACC).
B15: Crescimento na perpetuidade (g) | D15: =Premissas!$D$32 -> 0.035 | I15: A taxa à qual o caixa cresce para sempre depois de 2030 (aba Premissas).
B16: FCFF normalizado de 2030 | D16: =FCFF!D26 -> 52965.919 | I16: O FCFF de 2030 ajustado para repetir para sempre (aba FCFF).
B17: Valor terminal no fim do último ano | D17: =D16*(1+D15)/(D14-D15) -> 569989.38 | I17: FCFF normalizado × (1 + g) ÷ (WACC − g). Resume em um número todos os anos depois de 2030.
B18: Valor presente do valor terminal | D18: =D17/(1+D14)^H8 -> 327159.59 | I18: Valor terminal ÷ (1 + WACC) elevado aos anos até o fim de 2030.
B20: Do valor da empresa ao preço por ação
B21: Valor presente dos fluxos projetados | D21: =SUM($D$11:$H$11) -> 105265.59 | I21: Soma dos valores presentes de 2026 a 2030.
B22: Valor da empresa (Enterprise Value) | D22: =D21+D18 -> 432425.19 | I22: Valor presente dos fluxos + valor presente do valor terminal. Quanto vale a operação inteira.
B23: (-) Dívida líquida na data-base | D23: =Demonstrativos!K65 -> 68192 | I23: Sai: é dos credores (dívida bruta − caixa, no último balanço).
B24: (-) Participação de não controladores | D24: =Demonstrativos!K40 -> 4832 | I24: Sai: é dos sócios das controladas.
B25: (+) Investimentos em coligadas (valor contábil) | D25: =Demonstrativos!K31 -> 27248 | I25: Entra: participações em outras empresas, que o FCFF não contou.
B26: (-) Outros passivos tratados como dívida | D26: =Premissas!$D$34 -> 0 | I26: Sai: outros passivos que funcionam como dívida (aba Premissas).
B27: Valor do acionista (Equity Value) | D27: =D22-D23-D24+D25-D26 -> 386649.19 | I27: EV − dívida líquida − minoritários + investimentos − outros. Quanto vale a parte dos acionistas.
B28: Ações em circulação (milhões) | D28: =Premissas!$D$38 -> 4072.366 | I28: Número de ações em circulação, sem as que estão na tesouraria.
B29: Preço justo por ação | D29: =D27/D28 -> 94.944606 | I29: Valor do acionista ÷ número de ações.
B30: Preço de mercado | D30: =Premissas!$D$39 -> 67.64 | I30: Último fechamento na B3.
B31: Diferença para o preço de mercado | D31: =D29/D30-1 -> 0.40367543 | I31: Preço justo ÷ preço de mercado − 1.
B32: Peso do valor terminal no valor da empresa | D32: =D18/D22 -> 0.75656923 | I32: Quanto do valor da empresa vem de depois de 2030. Quanto maior, mais o resultado depende do longo prazo.
B33: EV / EBITDA 2026E implícito | D33: =D22/Projeção!D14 -> 5.7330553 | I33: Valor da empresa ÷ EBITDA de 2026: o múltiplo que o DCF está pagando.
B35: Conferência pelo fluxo do acionista (FCFE), descontado pelo Ke
B36: FCFE | D36: =FCFF!D22 -> 23038.504 | E36: =FCFF!E22 -> 25670.177 | F36: =FCFF!F22 -> 28742.718 | G36: =FCFF!G22 -> 32061.257 | H36: =FCFF!H22 -> 35665.578 | I36: O caixa livre do acionista de cada ano (aba FCFF).
B37: Fator de desconto pelo Ke | D37: =1/(1+WACC!$D$24)^D9 -> 0.96305723 | E37: =1/(1+WACC!$D$24)^E9 -> 0.86074583 | F37: =1/(1+WACC!$D$24)^F9 -> 0.74133823 | G37: =1/(1+WACC!$D$24)^G9 -> 0.63849554 | H37: =1/(1+WACC!$D$24)^H9 -> 0.54991977 | I37: 1 ÷ (1 + Ke) elevado ao número de anos.
B38: Valor presente do FCFE | D38: =D36*D7*D37 -> 11184.88 | E38: =E36*E7*E37 -> 22095.498 | F38: =F36*F7*F37 -> 21308.076 | G38: =G36*G7*G37 -> 20470.97 | H38: =H36*H7*H37 -> 19613.207 | I38: FCFE × parte do ano × fator de desconto.
B39: Custo do capital próprio (Ke) em uso | D39: =WACC!$D$24 -> 0.16107034 | I39: A taxa que desconta o caixa do acionista (aba WACC).
B40: FCFE normalizado de 2030 | D40: =FCFF!D27 -> 51464.67 | I40: O FCFE de 2030 ajustado para repetir para sempre (aba FCFF).
B41: Valor presente do valor terminal do FCFE | D41: =D40*(1+D15)/(D39-D15)/(1+D39)^H8 -> 215628.76 | I41: Valor terminal do FCFE trazido a valor de hoje pelo Ke.
B42: Valor do acionista pelo FCFE | D42: =SUM($D$38:$H$38)+D41-D24+D25-D26 -> 332717.39 | I42: Soma dos FCFE descontados, menos minoritários, mais investimentos. Deve ficar perto do valor pelo FCFF.
B43: Preço por ação pelo FCFE | D43: =D42/D28 -> 81.70125 | I43: Valor do acionista pelo FCFE ÷ número de ações.
B45: Sensibilidade do preço justo: WACC (linhas) x crescimento perpétuo (colunas)
...

Sheet Múltiplos
B1: Valuation por múltiplos
B2: Quanto o mercado paga pelas comparáveis, com os números dos últimos doze meses. A mediana das outras quatro, aplicada à empresa escolhida, dá um preço implícito.
B4: Empresa (R$ milhões) | C4: Setor | D4: Preço | E4: Ações (milhões) | F4: Valor de mercado | G4: Dívida líquida | H4: Minoritários | I4: EV | J4: EBITDA | K4: EBIT | L4: Lucro | M4: Patrimônio | N4: EV/EBITDA | O4: EV/EBIT | P4: P/L | Q4: P/VP
B5: Vale (VALE3) | C5: Mineração | D5: 67.64 | E5: 4072.366 | F5: 275454.84 | G5: 68192 | H5: 4832 | I5: =F5+G5+H5 -> 348478.84 | J5: 51933 | K5: 34110 | L5: 10369 | M5: 196635 | N5: =I5/J5 -> 6.7101619 | O5: =I5/K5 -> 10.216325 | P5: =IF(L5>0,F5/L5,"n.a.") -> 26.565227 | Q5: =F5/M5 -> 1.4008434
B6: CSN (CSNA3) | C6: Siderurgia | D6: 6.36 | E6: 1326.0939 | F6: 8433.9575 | G6: 39079.806 | H6: 3074.044 | I6: =F6+G6+H6 -> 50587.808 | J6: 7727.263 | K6: 3345.416 | L6: -2626.882 | M6: 12166.332 | N6: =I6/J6 -> 6.5466657 | O6: =I6/K6 -> 15.12153 | P6: =IF(L6>0,F6/L6,"n.a.") -> n.a. | Q6: =F6/M6 -> 0.69322105
B7: Gerdau (GGBR4) | C7: Siderurgia | D7: 24.77 | E7: 1963.1806 | F7: 46089.048 | G7: 8117.595 | H7: 190.194 | I7: =F7+G7+H7 -> 54396.837 | J7: 8730.516 | K7: 5034.141 | L7: 2237.081 | M7: 53544.554 | N7: =I7/J7 -> 6.2306554 | O7: =I7/K7 -> 10.805585 | P7: =IF(L7>0,F7/L7,"n.a.") -> 20.602315 | Q7: =F7/M7 -> 0.8607607
B8: Usiminas (USIM5) | C8: Siderurgia | D8: 7.21 | E8: 1230.9427 | F8: 8625.6879 | G8: -599.249 | H8: 2893.937 | I8: =F8+G8+H8 -> 10920.376 | J8: 164.986 | K8: -982.31 | L8: -2320.418 | M8: 20751.154 | N8: =I8/J8 -> 66.189712 | O8: =I8/K8 -> -11.117036 | P8: =IF(L8>0,F8/L8,"n.a.") -> n.a. | Q8: =F8/M8 -> 0.41567268
B9: CSN Mineração (CMIN3) | C9: Mineração | D9: 5.06 | E9: 5402.4354 | F9: 27336.323 | G9: 1025.104 | H9: 0.19 | I9: =F9+G9+H9 -> 28361.617 | J9: 6003.736 | K9: 4642.024 | L9: 2333.063 | M9: 7339.411 | N9: =I9/J9 -> 4.7239947 | O9: =I9/K9 -> 6.1097524 | P9: =IF(L9>0,F9/L9,"n.a.") -> 11.716925 | Q9: =F9/M9 -> 3.7245936
B11: Mediana das comparáveis de VALE3 (sem ela) | N11: =MEDIAN(N6,N7,N8,N9) -> 6.3886606 | O11: =MEDIAN(O6,O7,O8,O9) -> 8.4576685 | P11: =MEDIAN(P6,P7,P8,P9) -> 16.15962 | Q11: =MEDIAN(Q6,Q7,Q8,Q9) -> 0.77699088
B12: Mediana das comparáveis de CSNA3 (sem ela) | N12: =MEDIAN(N5,N7,N8,N9) -> 6.4704086 | O12: =MEDIAN(O5,O7,O8,O9) -> 8.1630386 | P12: =MEDIAN(P5,P7,P8,P9) -> 20.602315 | Q12: =MEDIAN(Q5,Q7,Q8,Q9) -> 1.130802
B13: Mediana das comparáveis de GGBR4 (sem ela) | N13: =MEDIAN(N5,N6,N8,N9) -> 6.6284138 | O13: =MEDIAN(O5,O6,O8,O9) -> 8.1630386 | P13: =MEDIAN(P5,P6,P8,P9) -> 19.141076 | Q13: =MEDIAN(Q5,Q6,Q8,Q9) -> 1.0470322
B15: ="Preço por ação implícito - "&Painel!$D$5 -> Preço por ação implícito - Vale (VALE3) | C15: R$ / ação | D15: Como se calcula
B16: Pelo EV/EBITDA das comparáveis | C16: =IF(INDEX(J5:J7,Painel!$Y$5)>0,(INDEX(N11:N13,Painel!$Y$5)*INDEX(J5:J7,Painel!$Y$5)-INDEX(G5:G7,Painel!$Y$5)-INDEX(H5:H7,Painel!$Y$5))/INDEX(E5:E7,Painel!$Y$5),"n.a.") -> 63.540042 | D16: Mediana × EBITDA da empresa, menos dívida líquida e minoritários, ÷ número de ações.
B17: Pelo EV/EBIT das comparáveis | C17: =IF(INDEX(K5:K7,Painel!$Y$5)>0,(INDEX(O11:O13,Painel!$Y$5)*INDEX(K5:K7,Painel!$Y$5)-INDEX(G5:G7,Painel!$Y$5)-INDEX(H5:H7,Painel!$Y$5))/INDEX(E5:E7,Painel!$Y$5),"n.a.") -> 52.909555 | D17: Mediana × EBIT da empresa, menos dívida líquida e minoritários, ÷ número de ações.
B18: Pelo P/L das comparáveis | C18: =IF(INDEX(L5:L7,Painel!$Y$5)>0,INDEX(P11:P13,Painel!$Y$5)*INDEX(L5:L7,Painel!$Y$5)/INDEX(E5:E7,Painel!$Y$5),"n.a.") -> 41.145393 | D18: Mediana × lucro da empresa ÷ número de ações. Não se aplica com prejuízo.
B19: Pelo P/VP das comparáveis | C19: =INDEX(Q11:Q13,Painel!$Y$5)*INDEX(M5:M7,Painel!$Y$5)/INDEX(E5:E7,Painel!$Y$5) -> 37.517159 | D19: Mediana × patrimônio dos controladores ÷ número de ações.
B20: Pelo fluxo de caixa descontado (aba Valor justo) | C20: ='Valor justo'!D29 -> 94.944606 | D20: Para comparar com os múltiplos.
B21: Preço de mercado | C21: =INDEX(D5:D7,Painel!$Y$5) -> 67.64 | D21: Último fechamento na B3.
B23: EV (valor da empresa) = valor de mercado + dívida líquida + minoritários.
B24: EV/EBITDA: quantos anos de EBITDA o mercado paga pela empresa inteira.
B25: P/L: quantos anos de lucro o mercado paga pela ação. P/VP: quanto paga por real de patrimônio.
B26: A mediana ignora os extremos: a Usiminas, com EBITDA perto de zero, tem EV/EBITDA fora da curva.

Sheet Cenários
B1: ="Cenários - "&Painel!$D$5 -> Cenários - Vale (VALE3)
B2: De onde vem e para onde vai o caixa em cada ano, no cenário em uso. Abaixo, os três cenários lado a lado.
B4: Entradas e saídas de caixa | D4: 2026E | E4: 2027E | F4: 2028E | G4: 2029E | H4: 2030E | I4: O que é
B5: Entradas (cash in)
B6: Caixa gerado pela operação (EBITDA sem equivalência) | D6: =Projeção!D14-Projeção!D13 -> 76996.655 | E6: =Projeção!E14-Projeção!E13 -> 82546.431 | F6: =Projeção!F14-Projeção!F13 -> 88407.998 | G6: =Projeção!G14-Projeção!G13 -> 94596.996 | H6: =Projeção!H14-Projeção!H13 -> 101129.81 | I6: EBITDA sem equivalência: o caixa que a operação produz.
B7: Rendimento do caixa | D7: =Projeção!D17 -> 3896.4744 | E7: =Projeção!E17 -> 3693.0219 | F7: =Projeção!F17 -> 3548.3343 | G7: =Projeção!G17 -> 3488.3238 | H7: =Projeção!H17 -> 3518.9725 | I7: Juros recebidos sobre o caixa aplicado.
B8: Captação líquida de dívida (se positiva) | D8: =MAX(0,Premissas!$D$19) -> 0 | E8: =MAX(0,Premissas!$E$19) -> 0 | F8: =MAX(0,Premissas!$F$19) -> 0 | G8: =MAX(0,Premissas!$G$19) -> 0 | H8: =MAX(0,Premissas!$H$19) -> 0 | I8: Dívida nova que entrou, se a captação líquida foi positiva.
B9: Total de entradas | D9: =D6+D7+D8 -> 80893.129 | E9: =E6+E7+E8 -> 86239.453 | F9: =F6+F7+F8 -> 91956.332 | G9: =G6+G7+G8 -> 98085.32 | H9: =H6+H7+H8 -> 104648.78 | I9: Soma das entradas.
B10: Saídas (cash out)
