Workbook

Sheet Resumo
B1: Valuation - Gerdau (GGBR4)
B2: Data-base 2026-06-30. Dados públicos da CVM e da B3. R$ milhões, salvo indicação.
B3: Estudo acadêmico e de portfólio. Não é recomendação de compra ou venda. O resultado depende das premissas da aba Premissas, que nesta versão são uma proposta automática ainda não revisada.
B5: Resultado no cenário em uso | D5: Valor
B6: Cenário | D6: ='Premissas'!D4
B7: Preço justo por ação (DCF) | D7: ='DCF'!$D$30
B8: Preço de mercado | D8: ='DCF'!D31
B9: Diferença para o mercado | D9: ='DCF'!$D$32
B10: Valor da empresa (EV) | D10: ='DCF'!$D$23
B11: Valor do acionista | D11: ='DCF'!$D$28
B12: WACC | D12: ='DCF'!D14
B13: Custo do capital próprio (Ke) | D13: ='DCF'!D40
B14: Crescimento na perpetuidade | D14: ='DCF'!D15
B15: Peso do valor terminal | D15: ='DCF'!D33
B16: Preço pelo fluxo do acionista (FCFE) | D16: ='DCF'!D44
B18: Como ler a planilha | D18: Aba
B19: Os três cenários, o ajuste manual e as demais entradas. Comece por aqui. | D19: Premissas
B20: DRE, balanço e fluxo de caixa da CVM, com indicadores. | D20: Histórico
B21: Receita, custos, capex, depreciação, giro e as três demonstrações ligadas. | D21: Projeção
B22: EV/EBITDA, P/L e P/VP contra as comparáveis. | D22: Múltiplos
B23: FCFF e FCFE descontados, valor da empresa, valor do acionista, sensibilidade. | D23: DCF
B24: CAPM, custo médio ponderado de capital e o ajuste do cenário. | D24: WACC
B25: Entradas e saídas de caixa e comparativo pessimista, moderado e otimista. | D25: Cenários

Sheet Premissas
B1: Premissas - Gerdau (GGBR4)
B2: Células azuis em fundo amarelo são entradas: troque e a planilha inteira recalcula. PROPOSTA AUTOMÁTICA, AINDA NÃO APROVADA
L3: Cenários
B4: Cenário em uso | D4: Moderado | L4: Pessimista
B5: Número do cenário (1 pessimista, 2 moderado, 3 otimista) | D5: =MATCH(D4,L4:L6,0) | L5: Moderado
L6: Otimista
B7: Variáveis de cenário | C7: Em uso | D7: Partida 2026 | E7: Pessimista | F7: Moderado | G7: Otimista | H7: Ajuste manual | I7: De onde veio
B8: Crescimento da receita, ao ano (2027 a 2030) | C8: =IF(ISNUMBER(H8),MIN(MAX(H8,MIN(E8:G8)),MAX(E8:G8)),CHOOSE($D$5,E8,F8,G8)) | D8: -0.0045 | E8: 0 | F8: 0.0378 | G8: 0.061 | I8: 2026: nível dos últimos 12 meses (LTM 2T26). Pessimista: receita parada, ou seja, queda real. Moderado: inflação esperada no Focus para 2027-2030, crescimento real zero. Otimista: crescimento médio da receita de 2018 a 2025 (6.1% ao ano).
B9: Margem EBITDA em 2030 | C9: =IF(ISNUMBER(H9),MIN(MAX(H9,MIN(E9:G9)),MAX(E9:G9)),CHOOSE($D$5,E9,F9,G9)) | D9: 0.1538 | E9: 0.1613 | F9: 0.1971 | G9: 0.2506 | I9: 2026: nível dos últimos 12 meses (LTM 2T26). Daí até 2030 em linha reta. Faixa: margem EBITDA de 2021 a 2025, sem perdas por recuperabilidade. Pessimista é o segundo pior ano, moderado a mediana e otimista o segundo melhor.
B10: WACC: pontos acima ou abaixo do CAPM | C10: =IF(ISNUMBER(H10),MIN(MAX(H10,MIN(E10:G10)),MAX(E10:G10)),CHOOSE($D$5,E10,F10,G10)) | E10: 0.0156 | F10: 0 | G10: -0.0156 | I10: Moderado: o WACC que sai do CAPM. O juro prefixado longo andou de 12.2% a 15.3% nos últimos dois anos; pessimista e otimista deslocam o WACC em metade dessa amplitude.
B11: Ajuste manual vazio = vale o cenário escolhido acima.
B13: Do cenário para cada ano (o que a projeção lê) | D13: 2026E | E13: 2027E | F13: 2028E | G13: 2029E | H13: 2030E
B14: Crescimento da receita | D14: =$D$8 | E14: =$C$8 | F14: =$C$8 | G14: =$C$8 | H14: =$C$8
B15: Margem EBITDA | D15: =$D$9+($C$9-$D$9)*0/4 | E15: =$D$9+($C$9-$D$9)*1/4 | F15: =$D$9+($C$9-$D$9)*2/4 | G15: =$D$9+($C$9-$D$9)*3/4 | H15: =$D$9+($C$9-$D$9)*4/4
B17: Premissas iguais nos três cenários (editáveis) | D17: 2026E | E17: 2027E | F17: 2028E | G17: 2029E | H17: 2030E | I17: De onde veio
B18: Despesas operacionais (% da receita) | D18: 0.0332 | E18: 0.0315 | F18: 0.0297 | G18: 0.0279 | H18: 0.0261 | I18: Vendas, administrativas e outras, sem perdas por recuperabilidade. Do nível dos últimos 12 meses até a mediana de 2021-2025.
B19: Equivalência patrimonial (R$ milhões) | D19: 563.158 | E19: 563.158 | F19: 563.158 | G19: 563.158 | H19: 563.158 | I19: Mediana de 2021-2025, mantida.
B20: Investimento - capex (% da receita) | D20: 0.0779 | E20: 0.0773 | F20: 0.0767 | G20: 0.0762 | H20: 0.0756 | I20: Do nível dos últimos 12 meses até a mediana de 2021-2025.
B21: Depreciação (% do ativo fixo inicial) | D21: 0.0887 | E21: 0.0887 | F21: 0.0887 | G21: 0.0887 | H21: 0.0887 | I21: Mediana de 2021-2025, mantida.
B22: Prazo médio de recebimento (dias) | D22: 25.1348 | E22: 25.1348 | F22: 25.1348 | G22: 25.1348 | H22: 25.1348 | I22: Prazo de 2025, mantido.
B23: Prazo médio de estoque (dias) | D23: 92.3738 | E23: 92.3738 | F23: 92.3738 | G23: 92.3738 | H23: 92.3738 | I23: Prazo de 2025, mantido.
B24: Prazo médio de pagamento (dias) | D24: 31.414 | E24: 31.414 | F24: 31.414 | G24: 31.414 | H24: 31.414 | I24: Prazo de 2025, mantido.
B25: Captação líquida de dívida (R$ milhões) | D25: 0 | E25: 0 | F25: 0 | G25: 0 | H25: 0 | I25: Dívida bruta mantida no nível de 2025.
B27: Premissas gerais | D27: Valor | I27: De onde veio
B28: Alíquota de IR e CSLL | D28: 0.34 | I28: Alíquota nominal: IRPJ 25% + CSLL 9%.
B29: Custo da dívida antes do imposto (Kd) | D29: 0.1291 | I29: Piso: a taxa do Tesouro prefixado de dez anos, sem spread de crédito. Custo implícito mediano 2023-2025: 19.3%.
B30: Rendimento do caixa | D30: 0.1235 | I30: Mediana 2023-2025 da receita financeira sobre o caixa médio.
B31: Dividendos (% do lucro) | D31: 0.3602 | I31: Mediana 2021-2025 de dividendos pagos sobre lucro, limitada a 0-100%.
B32: Juro sem risco (Rf) | D32: 0.1291 | I32: Tesouro prefixado de dez anos (em reais, nominal).
B33: Beta | D33: 0.801 | I33: Regressão de 5 anos, retornos semanais contra o BOVA11, preços sem ajuste de proventos. Beta de 2 anos: 0.71.
B34: Prêmio de risco de mercado | D34: 0.0423 | I34: Damodaran, mercado maduro. O risco-país já está no juro em reais.
B35: Prêmio adicional (tamanho, risco específico) | D35: 0 | I35: Sem prêmio adicional.
B36: Peso da dívida na estrutura de capital | D36: 0.2273 | I36: Dívida bruta do 2T26 sobre dívida mais valor de mercado.
B37: Crescimento na perpetuidade (g) | D37: 0.035 | I37: IPCA esperado para 2030: crescimento real zero.
B38: Capex na perpetuidade (múltiplo da depreciação) | D38: 1 | I38: Na perpetuidade a empresa reinveste o que deprecia.
B39: Outros passivos tratados como dívida (R$ milhões) | D39: 0 | I39: Nenhum. Provisões (barragens, contingências) não entram como dívida.
B41: Dados de mercado e datas | D41: Valor | I41: Fonte
B42: Data-base do valuation | D42: 46203 | I42: Último ITR.
B43: Fração de 2026 que ainda falta | D43: =(DATE(2026,12,31)-D42)/365 | I43: Só essa parte do fluxo de 2026 entra no valor.
B44: Ações em circulação (milhões) | D44: 1963.1806 | I44: CVM, composição do capital em 2026-06-30, sem tesouraria.
...

Sheet Histórico
B1: Histórico - Gerdau
B2: Fonte: demonstrações consolidadas entregues à CVM (DFP e ITR). LTM = últimos doze meses; o balanço é o do trimestre.
B4: R$ milhões | C4: 2018 | D4: 2019 | E4: 2020 | F4: 2021 | G4: 2022 | H4: 2023 | I4: 2024 | J4: 2025 | K4: LTM 2T26
B5: Demonstração do resultado
B6: Receita líquida | C6: 46159.478 | D6: 39644.01 | E6: 43814.661 | F6: 78345.081 | G6: 82412.21 | H6: 68916.447 | I6: 67026.656 | J6: 69858.532 | K6: 69543.739
B7: Custo dos produtos vendidos | C7: -40010.1 | D7: -35440.726 | E7: -37884.102 | F7: -57527.721 | G7: -63661.156 | H7: -57583.992 | I7: -57823.416 | J7: -61891.039 | K7: -60430.291
B8: Lucro bruto | C8: 6149.378 | D8: 4203.284 | E8: 5930.559 | F8: 20817.36 | G8: 18751.054 | H8: 11332.455 | I8: 9203.24 | J8: 7967.493 | K8: 9113.448
B9: Despesas com vendas | C9: -580.345 | D9: -476.339 | E9: -512.95 | F9: -715.83 | G9: -733.026 | H9: -716.195 | I9: -762.56 | J9: -782.351 | K9: -757.79
B10: Despesas gerais e administrativas | C10: -1082.449 | D10: -954.117 | E10: -1017.435 | F10: -1390.121 | G10: -1454.592 | H10: -1491.441 | I10: -1404.059 | J10: -1338.443 | K10: -1302.351
B11: Perdas por recuperabilidade de ativos (impairment) | C11: 0 | D11: 0 | E11: -411.925 | F11: 0 | G11: 0 | H11: 0 | I11: -199.627 | J11: -1964.504 | K11: -1964.504
B12: Total de despesas/receitas operacionais | C12: -2102.152 | D12: -1019.35 | E12: -736.174 | F12: 205.662 | G12: -999.601 | H12: -879.728 | I12: -1716.038 | J12: -4228.425 | K12: -4079.307
B13: Equivalência patrimonial | C13: 10.141 | D13: -17.05 | E13: 152.569 | F13: 563.158 | G13: 1151.827 | H13: 827.606 | I13: 464.467 | J13: 95.622 | K13: 196.604
B14: EBIT (resultado antes do financeiro e dos tributos) | C14: 4047.226 | D14: 3183.934 | E14: 5194.385 | F14: 21023.022 | G14: 17751.453 | H14: 10452.727 | I14: 7487.202 | J14: 3739.068 | K14: 5034.141
B15: Resultado financeiro | C15: -1889.795 | D15: -1509.214 | E15: -1698.707 | F15: -750.454 | G15: -1892.426 | H15: -1106.122 | I15: -2023.487 | J15: -1214.621 | K15: -1200.23
B16: Lucro antes dos tributos | C16: 2157.431 | D16: 1674.72 | E16: 3495.678 | F16: 20272.568 | G16: 15859.027 | H16: 9346.605 | I16: 5463.715 | J16: 2524.447 | K16: 3833.911
B17: Imposto de renda e CSLL | C17: 168.951 | D17: -457.833 | E17: -1107.624 | F17: -4713.63 | G17: -4379.475 | H17: -1809.622 | I17: -864.653 | J17: -1106.009 | K17: -1558.373
... B19: Lucro atribuído aos controladores | C19: 2303.868 | D19: 1203.736 | E19: 2365.763 | F19: 15494.111 | G19: 11425.512 | H19: 7501.565 | I19: 4566.317 | J19: 1387.02 | K19: 2237.081
B20: Fluxo de caixa
B21: Depreciação, amortização e exaustão | C21: 1891.814 | D21: 2074.295 | E21: 2441.835 | F21: 2515.909 | G21: 2899.239 | H21: 3130.548 | I21: 3126.247 | J21: 3683.585 | K21: 3696.375
B22: Caixa das atividades operacionais | C22: 1999.683 | D22: 1642.792 | E22: 6407.906 | F22: 12516.933 | G22: 11150.338 | H22: 11138.71 | I22: 11381.243 | J22: 7987.454 | K22: 9116.445
B23: Investimento em imobilizado e intangível (capex) | C23: 1194.934 | D23: 1746.6 | E23: 1650.778 | F23: 3026.023 | G23: 4291.873 | H23: 5209.128 | I23: 5778.381 | J23: 6681.62 | K23: 5415.708
B24: Dividendos e JCP pagos | C24: 599.099 | D24: 484.173 | E24: 274.815 | F24: 5339.426 | G24: 5891.69 | H24: 2683.328 | I24: 1656.414 | J24: 1285.673 | K24: 1372.327
B25: Balanço patrimonial
B26: Caixa e equivalentes | C26: 2890.144 | D26: 2641.652 | E26: 4617.204 | F26: 4160.654 | G26: 2475.863 | H26: 3005.645 | I26: 7767.813 | J26: 5929.17 | K26: 5155.232
B27: Aplicações financeiras | C27: 459.47 | D27: 3652.949 | E27: 3041.143 | F27: 2626.212 | G27: 2959.135 | H27: 2338.097 | I27: 509.03 | J27: 445.627 | K27: 285.262
B28: Contas a receber | C28: 3201.656 | D28: 2672.37 | E28: 3737.27 | F28: 5414.075 | G28: 4999.004 | H28: 4875.394 | I28: 5176.958 | J28: 4810.64 | K28: 5999.384
B29: Estoques | C29: 9167.689 | D29: 7659.737 | E29: 9169.417 | F29: 16861.488 | G29: 17817.585 | H29: 15227.778 | I29: 16504.911 | J29: 14731.081 | K29: 16099.611
B30: Ativo circulante | C30: 17503.082 | D30: 18235.713 | E30: 23409.453 | F30: 32640.477 | G30: 31257.422 | H30: 29197.937 | I30: 32669.423 | J30: 28605.081 | K30: 29438.649
B31: Investimentos em coligadas | C31: 1367.802 | D31: 1812.399 | E31: 2271.629 | F31: 3340.775 | G31: 3896.518 | H31: 3858.449 | I31: 4222.317 | J31: 3944.474 | K31: 3700.806
B32: Imobilizado | C32: 15546.481 | D32: 16678.807 | E32: 18068.226 | F32: 19603.53 | G32: 21383.61 | H32: 24063.184 | I32: 30760.008 | J32: 31912.295 | K32: 32283.184
B33: Intangível | C33: 9948.486 | D33: 10142.573 | E33: 12726.097 | F33: 12937.287 | G33: 12049.623 | H33: 11198.858 | I33: 14253.681 | J33: 12687.092 | K33: 11969.463
B34: Ativo total | C34: 51281.029 | D34: 54002.97 | E34: 63123.009 | F34: 73814.613 | G34: 73798.652 | H34: 74885.144 | I34: 86814.493 | J34: 81688.175 | K34: 81972.713
B35: Fornecedores | C35: 4119.057 | D35: 3762.768 | E35: 5437.953 | F35: 8017.14 | G35: 6618.923 | H35: 5901.183 | I35: 5718.104 | J35: 5009.671 | K35: 6181.971
B36: Empréstimos e financiamentos - curto prazo | C36: 1824.938 | D36: 1562.226 | E36: 1431.506 | F36: 1766.493 | G36: 3121.148 | H36: 1797.622 | I36: 735.037 | J36: 941.904 | K36: 629.75
B37: Passivo circulante | C37: 8504.253 | D37: 7424.537 | E37: 11482.143 | F37: 14036.814 | G37: 13462.581 | H37: 11284.612 | I37: 10851.391 | J37: 9887.42 | K37: 10257.691
... B40: Participação de não controladores | C40: 207.967 | D40: 217.426 | E40: 224.939 | F40: 211.367 | G40: 181.999 | H40: 179.904 | I40: 225.027 | J40: 213.096 | K40: 190.194
B41: Indicadores (fórmulas)
B42: EBITDA (EBIT + depreciação) | C42: =C14+C21 | D42: =D14+D21 | E42: =E14+E21 | F42: =F14+F21 | G42: =G14+G21 | H42: =H14+H21 | I42: =I14+I21 | J42: =J14+J21 | K42: =K14+K21
B43: EBITDA sem perdas por recuperabilidade | C43: =C42-C11 | D43: =D42-D11 | E43: =E42-E11 | F43: =F42-F11 | G43: =G42-G11 | H43: =H42-H11 | I43: =I42-I11 | J43: =J42-J11 | K43: =K42-K11
B44: Margem EBITDA sem perdas por recuperabilidade | C44: =C43/C6 | D44: =D43/D6 | E44: =E43/E6 | F44: =F43/F6 | G44: =G43/G6 | H44: =H43/H6 | I44: =I43/I6 | J44: =J43/J6 | K44: =K43/K6
...

Sheet Projeção
B1: Projeção - Gerdau
B2: DRE, balanço e fluxo de caixa ligados. Custos e despesas em valor positivo. 2025 é o realizado; os demais anos são fórmulas sobre as premissas.
B4: R$ milhões | C4: 2025 | D4: 2026E | E4: 2027E | F4: 2028E | G4: 2029E | H4: 2030E
B5: Demonstração do resultado
B6: Receita líquida | C6: ='Histórico'!J6 | D6: =C6*(1+'Premissas'!D14) | E6: =D6*(1+'Premissas'!E14) | F6: =E6*(1+'Premissas'!F14) | G6: =F6*(1+'Premissas'!G14) | H6: =G6*(1+'Premissas'!H14)
B7: (-) Custo dos produtos (sem depreciação) | C7: =-'Histórico'!J45 | D7: =D6-D8+D9-D10 | E7: =E6-E8+E9-E10 | F7: =F6-F8+F9-F10 | G7: =G6-G8+G9-G10 | H7: =H6-H8+H9-H10
B8: (-) Despesas operacionais (vendas, administrativas e outras) | C8: =-('Histórico'!J9+'Histórico'!J10+'Histórico'!J46) | D8: =D6*'Premissas'!D18 | E8: =E6*'Premissas'!E18 | F8: =F6*'Premissas'!F18 | G8: =G6*'Premissas'!G18 | H8: =H6*'Premissas'!H18
B9: (+/-) Equivalência patrimonial | C9: ='Histórico'!J13 | D9: ='Premissas'!D19 | E9: ='Premissas'!E19 | F9: ='Premissas'!F19 | G9: ='Premissas'!G19 | H9: ='Premissas'!H19
B10: EBITDA | C10: =C6-C7-C8+C9 | D10: =D6*'Premissas'!D15 | E10: =E6*'Premissas'!E15 | F10: =F6*'Premissas'!F15 | G10: =G6*'Premissas'!G15 | H10: =H6*'Premissas'!H15
B11: (-) Depreciação e amortização | C11: ='Histórico'!J21 | D11: =C23*'Premissas'!D21 | E11: =D23*'Premissas'!E21 | F11: =E23*'Premissas'!F21 | G11: =F23*'Premissas'!G21 | H11: =G23*'Premissas'!H21
B12: EBIT | C12: =C10-C11 | D12: =D10-D11 | E12: =E10-E11 | F12: =F10-F11 | G12: =G10-G11 | H12: =H10-H11
B13: (+) Rendimento do caixa | D13: =C38*'Premissas'!$D$30 | E13: =D38*'Premissas'!$D$30 | F13: =E38*'Premissas'!$D$30 | G13: =F38*'Premissas'!$D$30 | H13: =G38*'Premissas'!$D$30
B14: (-) Juros da dívida | D14: =C42*'Premissas'!$D$29 | E14: =D42*'Premissas'!$D$29 | F14: =E42*'Premissas'!$D$29 | G14: =F42*'Premissas'!$D$29 | H14: =G42*'Premissas'!$D$29
B15: (+/-) Resultado financeiro | C15: ='Histórico'!J15 | D15: =D13-D14 | E15: =E13-E14 | F15: =F13-F14 | G15: =G13-G14 | H15: =H13-H14
B16: Lucro antes dos tributos | C16: =C12+C15 | D16: =D12+D15 | E16: =E12+E15 | F16: =F12+F15 | G16: =G12+G15 | H16: =H12+H15
B17: (-) Imposto de renda e CSLL | C17: =-'Histórico'!J17 | D17: =MAX(0,D16-D9)*'Premissas'!$D$28 | E17: =MAX(0,E16-E9)*'Premissas'!$D$28 | F17: =MAX(0,F16-F9)*'Premissas'!$D$28 | G17: =MAX(0,G16-G9)*'Premissas'!$D$28 | H17: =MAX(0,H16-H9)*'Premissas'!$D$28
B18: Lucro líquido | C18: =C16-C17 | D18: =D16-D17 | E18: =E16-E17 | F18: =F16-F17 | G18: =G16-G17 | H18: =H16-H17
B19: NOPAT (EBIT sem equivalência, após imposto) | C19: =(C12-C9)*(1-'Premissas'!$D$28) | D19: =(D12-D9)*(1-'Premissas'!$D$28) | E19: =(E12-E9)*(1-'Premissas'!$D$28) | F19: =(F12-F9)*(1-'Premissas'!$D$28) | G19: =(G12-G9)*(1-'Premissas'!$D$28) | H19: =(H12-H9)*(1-'Premissas'!$D$28)
B21: Investimento, depreciação e capital de giro
B22: Capex | C22: ='Histórico'!J23 | D22: =D6*'Premissas'!D20 | E22: =E6*'Premissas'!E20 | F22: =F6*'Premissas'!F20 | G22: =G6*'Premissas'!G20 | H22: =H6*'Premissas'!H20
B23: Ativo fixo (imobilizado + intangível) | C23: ='Histórico'!J55 | D23: =C23+D22-D11 | E23: =D23+E22-E11 | F23: =E23+F22-F11 | G23: =F23+G22-G11 | H23: =G23+H22-H11
B24: Contas a receber | C24: ='Histórico'!J28 | D24: =D6*'Premissas'!D22/365 | E24: =E6*'Premissas'!E22/365 | F24: =F6*'Premissas'!F22/365 | G24: =G6*'Premissas'!G22/365 | H24: =H6*'Premissas'!H22/365
B25: Estoques | C25: ='Histórico'!J29 | D25: =D7*'Premissas'!D23/365 | E25: =E7*'Premissas'!E23/365 | F25: =F7*'Premissas'!F23/365 | G25: =G7*'Premissas'!G23/365 | H25: =H7*'Premissas'!H23/365
B26: Fornecedores | C26: ='Histórico'!J35 | D26: =D7*'Premissas'!D24/365 | E26: =E7*'Premissas'!E24/365 | F26: =F7*'Premissas'!F24/365 | G26: =G7*'Premissas'!G24/365 | H26: =H7*'Premissas'!H24/365
B27: Capital de giro | C27: =C24+C25-C26 | D27: =D24+D25-D26 | E27: =E24+E25-E26 | F27: =F24+F25-F26 | G27: =G24+G25-G26 | H27: =H24+H25-H26
B28: Variação do capital de giro (investimento em giro) | D28: =D27-C27 | E28: =E27-D27 | F28: =F27-E27 | G28: =G27-F27 | H28: =H27-G27
B30: Fluxos de caixa livres
B31: FCFF - fluxo de caixa livre da empresa | D31: =D19+D11-D22-D28 | E31: =E19+E11-E22-E28 | F31: =F19+F11-F22-F28 | G31: =G19+G11-G22-G28 | H31: =H19+H11-H22-H28
B32: (+) Captação líquida de dívida | D32: ='Premissas'!D25 | E32: ='Premissas'!E25 | F32: ='Premissas'!F25 | G32: ='Premissas'!G25 | H32: ='Premissas'!H25
B33: FCFE - fluxo de caixa livre do acionista | D33: =D18-D9+D11-D22-D28+D32 | E33: =E18-E9+E11-E22-E28+E32 | F33: =F18-F9+F11-F22-F28+F32 | G33: =G18-G9+G11-G22-G28+G32 | H33: =H18-H9+H11-H22-H28+H32
B34: (-) Dividendos | D34: =MAX(0,D18)*'Premissas'!$D$31 | E34: =MAX(0,E18)*'Premissas'!$D$31 | F34: =MAX(0,F18)*'Premissas'!$D$31 | G34: =MAX(0,G18)*'Premissas'!$D$31 | H34: =MAX(0,H18)*'Premissas'!$D$31
B35: Variação do caixa | D35: =D33-D34 | E35: =E33-E34 | F35: =F33-F34 | G35: =G33-G34 | H35: =H33-H34
B37: Balanço patrimonial resumido
B38: Caixa e aplicações | C38: ='Histórico'!J63 | D38: =C38+D35 | E38: =D38+E35 | F38: =E38+F35 | G38: =F38+G35 | H38: =G38+H35
B39: Investimentos em coligadas | C39: ='Histórico'!J31 | D39: =C39+D9 | E39: =D39+E9 | F39: =E39+F9 | G39: =F39+G9 | H39: =G39+H9
B40: Outros ativos (mantidos) | C40: ='Histórico'!J34-C38-C24-C25-C23-C39 | D40: =C40 | E40: =D40 | F40: =E40 | G40: =F40 | H40: =G40
B41: Ativo total | C41: =C38+C24+C25+C23+C39+C40 | D41: =D38+D24+D25+D23+D39+D40 | E41: =E38+E24+E25+E23+E39+E40 | F41: =F38+F24+F25+F23+F39+F40 | G41: =G38+G24+G25+G23+G39+G40 | H41: =H38+H24+H25+H23+H39+H40
B42: Dívida bruta | C42: ='Histórico'!J64 | D42: =C42+D32 | E42: =D42+E32 | F42: =E42+F32 | G42: =F42+G32 | H42: =G42+H32
B43: Outros passivos (mantidos) | C43: ='Histórico'!J34-C26-C42-C44 | D43: =C43 | E43: =D43 | F43: =E43 | G43: =F43 | H43: =G43
B44: Patrimônio líquido | C44: ='Histórico'!J39 | D44: =C44+D18-D34 | E44: =D44+E18-E34 | F44: =E44+F18-F34 | G44: =F44+G18-G34 | H44: =G44+H18-H34
...

Sheet Múltiplos
B1: Valuation por múltiplos
B2: Últimos doze meses. A mediana das comparáveis é aplicada aos números da empresa.
B4: Empresa (R$ milhões) | C4: Setor | D4: Preço | E4: Valor de mercado | F4: Dívida líquida | G4: Minoritários | H4: EV | I4: EBITDA | J4: EBIT | K4: Lucro | L4: Patrimônio | M4: EV/EBITDA | N4: EV/EBIT | O4: P/L | P4: P/VP
B5: Gerdau (GGBR4) | C5: Siderurgia | D5: 24.77 | E5: 46089.048 | F5: 8117.595 | G5: 190.194 | H5: =E5+F5+G5 | I5: 8730.516 | J5: 5034.141 | K5: 2237.081 | L5: 53544.554 | M5: =H5/I5 | N5: =H5/J5 | O5: =IF(K5>0,E5/K5,"n.a.") | P5: =E5/L5
B6: Vale (VALE3) | C6: Mineração | D6: 67.64 | E6: 275454.84 | F6: 68192 | G6: 4832 | H6: =E6+F6+G6 | I6: 51933 | J6: 34110 | K6: 10369 | L6: 196635 | M6: =H6/I6 | N6: =H6/J6 | O6: =IF(K6>0,E6/K6,"n.a.") | P6: =E6/L6
B7: CSN (CSNA3) | C7: Siderurgia | D7: 6.36 | E7: 8433.9575 | F7: 39079.806 | G7: 3074.044 | H7: =E7+F7+G7 | I7: 7727.263 | J7: 3345.416 | K7: -2626.882 | L7: 12166.332 | M7: =H7/I7 | N7: =H7/J7 | O7: =IF(K7>0,E7/K7,"n.a.") | P7: =E7/L7
B8: Usiminas (USIM5) | C8: Siderurgia | D8: 7.21 | E8: 8625.6879 | F8: -599.249 | G8: 2893.937 | H8: =E8+F8+G8 | I8: 164.986 | J8: -982.31 | K8: -2320.418 | L8: 20751.154 | M8: =H8/I8 | N8: =H8/J8 | O8: =IF(K8>0,E8/K8,"n.a.") | P8: =E8/L8
B9: CSN Mineração (CMIN3) | C9: Mineração | D9: 5.06 | E9: 27336.323 | F9: 1025.104 | G9: 0.19 | H9: =E9+F9+G9 | I9: 6003.736 | J9: 4642.024 | K9: 2333.063 | L9: 7339.411 | M9: =H9/I9 | N9: =H9/J9 | O9: =IF(K9>0,E9/K9,"n.a.") | P9: =E9/L9
B10: Mediana das comparáveis (sem a empresa) | M10: =MEDIAN(M6:M9) | N10: =MEDIAN(N6:N9) | O10: =MEDIAN(O6:O9) | P10: =MEDIAN(P6:P9)
B12: Preço por ação implícito | C12: R$ / ação | D12: Como
B13: Pelo EV/EBITDA das comparáveis | C13: =IF(I5>0,(M10*I5-F5-G5)/(E5/D5),"n.a.") | D13: Mediana x EBITDA, menos dívida líquida e minoritários
B14: Pelo EV/EBIT das comparáveis | C14: =IF(J5>0,(N10*J5-F5-G5)/(E5/D5),"n.a.") | D14: Mediana x EBIT, menos dívida líquida e minoritários
B15: Pelo P/L das comparáveis | C15: =IF(K5>0,O10*K5/(E5/D5),"n.a.") | D15: Mediana x lucro (não se aplica com prejuízo)
B16: Pelo P/VP das comparáveis | C16: =P10*L5/(E5/D5) | D16: Mediana x patrimônio dos controladores
B17: Pelo fluxo de caixa descontado (aba DCF) | C17: ='DCF'!$D$30 | D17: Para comparar
B18: Preço de mercado | C18: =D5

Sheet DCF
B1: Fluxo de caixa descontado - Gerdau
B2: O valor da empresa é a soma dos fluxos de caixa futuros trazidos a valor de hoje.
B4: R$ milhões | D4: 2026E | E4: 2027E | F4: 2028E | G4: 2029E | H4: 2030E
B5: Fluxo da empresa (FCFF), descontado pelo WACC
B6: FCFF | D6: ='Projeção'!D31 | E6: ='Projeção'!E31 | F6: ='Projeção'!F31 | G6: ='Projeção'!G31 | H6: ='Projeção'!H31
B7: Parte do ano que entra no valor | D7: ='Premissas'!$D$43 | E7: 1 | F7: 1 | G7: 1 | H7: 1
B8: Fim do período (anos desde a data-base) | D8: =D7 | E8: =D8+1 | F8: =E8+1 | G8: =F8+1 | H8: =G8+1
B9: Meio do período (quando o caixa entra, em média) | D9: =D8-D7/2 | E9: =E8-E7/2 | F9: =F8-F7/2 | G9: =G8-G7/2 | H9: =H8-H7/2
B10: Fator de desconto | D10: =1/(1+'WACC'!$D$23)^D9 | E10: =1/(1+'WACC'!$D$23)^E9 | F10: =1/(1+'WACC'!$D$23)^F9 | G10: =1/(1+'WACC'!$D$23)^G9 | H10: =1/(1+'WACC'!$D$23)^H9
B11: Valor presente do fluxo | D11: =D6*D7*D10 | E11: =E6*E7*E10 | F11: =F6*F7*F10 | G11: =G6*G7*G10 | H11: =H6*H7*H10
B13: Perpetuidade (Gordon)
B14: WACC | D14: ='WACC'!$D$23
B15: Crescimento na perpetuidade (g) | D15: ='Premissas'!$D$37
B16: FCFF normalizado de 2030 | D16: ='Projeção'!H19+'Projeção'!H11-'Premissas'!$D$38*'Projeção'!H11-'Projeção'!H28 | I16: NOPAT + depreciação - capex de reposição - investimento em giro
B17: Valor terminal no fim do último ano | D17: =D16*(1+D15)/(D14-D15) | I17: FCFF x (1 + g) / (WACC - g)
B18: Valor presente do valor terminal | D18: =D17/(1+D14)^H8
B20: Do valor da empresa ao preço por ação
B21: Valor presente dos fluxos projetados | D21: =SUM($D$11:$H$11)
B22: (+) Valor presente do valor terminal | D22: =D18
B23: Valor da empresa (Enterprise Value) | D23: =D21+D22
B24: (-) Dívida líquida na data-base | D24: ='Histórico'!K65
B25: (-) Participação de não controladores | D25: ='Histórico'!K40
B26: (+) Investimentos em coligadas (valor contábil) | D26: ='Histórico'!K31 | I26: O FCFF não inclui a equivalência; as coligadas entram pelo valor do balanço.
B27: (-) Outros passivos tratados como dívida | D27: ='Premissas'!$D$39
B28: Valor do acionista (Equity Value) | D28: =D23-D24-D25+D26-D27
B29: Ações em circulação (milhões) | D29: ='Premissas'!$D$44
B30: Preço justo por ação | D30: =D28/D29
B31: Preço de mercado | D31: ='Premissas'!$D$45
B32: Diferença para o preço de mercado | D32: =D30/D31-1
B33: Peso do valor terminal no valor da empresa | D33: =D18/D23
B34: EV / EBITDA 2026E implícito | D34: =D23/'Projeção'!D10
B36: Conferência pelo fluxo do acionista (FCFE), descontado pelo Ke
B37: FCFE | D37: ='Projeção'!D33 | E37: ='Projeção'!E33 | F37: ='Projeção'!F33 | G37: ='Projeção'!G33 | H37: ='Projeção'!H33
B38: Fator de desconto | D38: =1/(1+'WACC'!$D$24)^D9 | E38: =1/(1+'WACC'!$D$24)^E9 | F38: =1/(1+'WACC'!$D$24)^F9 | G38: =1/(1+'WACC'!$D$24)^G9 | H38: =1/(1+'WACC'!$D$24)^H9
B39: Valor presente do fluxo | D39: =D37*D7*D38 | E39: =E37*E7*E38 | F39: =F37*F7*F38 | G39: =G37*G7*G38 | H39: =H37*H7*H38
B40: Custo do capital próprio (Ke) | D40: ='WACC'!$D$24
B41: FCFE normalizado de 2030 | D41: ='Projeção'!H18-'Projeção'!H9+'Projeção'!H11-'Premissas'!$D$38*'Projeção'!H11-'Projeção'!H28+'Projeção'!H32
B42: Valor presente do valor terminal | D42: =D41*(1+D15)/(D40-D15)/(1+D40)^H8
B43: Valor do acionista pelo FCFE | D43: =SUM($D$39:$H$39)+D42-D25+D26-D27
B44: Preço por ação pelo FCFE | D44: =D43/D29
...

Sheet WACC
B1: Custo de capital
B2: CAPM para o capital próprio; WACC é a média com o custo da dívida depois do imposto.
B4: Capital próprio (CAPM) | D4: Valor | E4: Conta
B5: Juro sem risco (Rf) | D5: ='Premissas'!$D$32
B6: Beta | D6: ='Premissas'!$D$33
B7: Prêmio de risco de mercado | D7: ='Premissas'!$D$34
B8: Prêmio adicional | D8: ='Premissas'!$D$35
B9: Custo do capital próprio (Ke) | D9: =D5+D6*D7+D8 | E9: Ke = Rf + beta x prêmio de mercado + prêmio adicional
B11: Dívida | D11: Valor | E11: Conta
B12: Custo da dívida antes do imposto (Kd) | D12: ='Premissas'!$D$29
B13: Alíquota de IR e CSLL | D13: ='Premissas'!$D$28
B14: Custo da dívida após o imposto | D14: =D12*(1-D13) | E14: Juro é dedutível: Kd x (1 - alíquota)
B16: Média ponderada | D16: Valor | E16: Conta
B17: Peso da dívida | D17: ='Premissas'!$D$36
B18: Peso do capital próprio | D18: =1-D17
B19: WACC pelo CAPM | D19: =D9*D18+D14*D17 | E19: WACC = Ke x peso do capital próprio + Kd após imposto x peso da dívida
B21: Cenário | D21: Valor | E21: Conta
B22: Ajuste do cenário (pontos sobre o CAPM) | D22: ='Premissas'!$C$10 | E22: Da aba Premissas: zero no moderado, positivo no pessimista, negativo no otimista.
B23: WACC em uso | D23: =D19+D22 | E23: É a taxa que desconta o fluxo da empresa (FCFF) na aba DCF.
B24: Ke em uso | D24: =D9+D22 | E24: O mesmo ajuste no custo do capital próprio, que desconta o FCFE.
B26: Referência: estrutura a valor de mercado | D26: Valor | E26: Conta
B27: Valor de mercado (R$ milhões) | D27: ='Premissas'!$D$46
B28: Dívida bruta na data-base (R$ milhões) | D28: ='Histórico'!K64
B29: Peso da dívida a valor de mercado | D29: =D28/(D28+D27) | E29: Compare com o peso usado acima.

Sheet Cenários
B1: Cenários e movimento do caixa
B2: Troque o cenário na aba Premissas (célula D4) ou ajuste uma variável à mão: tudo abaixo e o resto da planilha seguem.
B4: Cenário em uso | D4: ='Premissas'!D4
B6: Entradas e saídas de caixa | D6: 2026E | E6: 2027E | F6: 2028E | G6: 2029E | H6: 2030E
B7: Entradas (cash in)
B8: Caixa gerado pela operação (EBITDA sem equivalência) | D8: ='Projeção'!D10-'Projeção'!D9 | E8: ='Projeção'!E10-'Projeção'!E9 | F8: ='Projeção'!F10-'Projeção'!F9 | G8: ='Projeção'!G10-'Projeção'!G9 | H8: ='Projeção'!H10-'Projeção'!H9
B9: Rendimento do caixa | D9: ='Projeção'!C38*'Premissas'!$D$30 | E9: ='Projeção'!D38*'Premissas'!$D$30 | F9: ='Projeção'!E38*'Premissas'!$D$30 | G9: ='Projeção'!F38*'Premissas'!$D$30 | H9: ='Projeção'!G38*'Premissas'!$D$30
B10: Captação líquida de dívida (se positiva) | D10: =MAX(0,'Projeção'!D32) | E10: =MAX(0,'Projeção'!E32) | F10: =MAX(0,'Projeção'!F32) | G10: =MAX(0,'Projeção'!G32) | H10: =MAX(0,'Projeção'!H32)
B11: Total de entradas | D11: =D8+D9+D10 | E11: =E8+E9+E10 | F11: =F8+F9+F10 | G11: =G8+G9+G10 | H11: =H8+H9+H10
B12: Saídas (cash out)
B13: Imposto de renda e CSLL | D13: ='Projeção'!D17 | E13: ='Projeção'!E17 | F13: ='Projeção'!F17 | G13: ='Projeção'!G17 | H13: ='Projeção'!H17
B14: Capex | D14: ='Projeção'!D22 | E14: ='Projeção'!E22 | F14: ='Projeção'!F22 | G14: ='Projeção'!G22 | H14: ='Projeção'!H22
B15: Investimento em capital de giro | D15: ='Projeção'!D28 | E15: ='Projeção'!E28 | F15: ='Projeção'!F28 | G15: ='Projeção'!G28 | H15: ='Projeção'!H28
B16: Juros da dívida | D16: ='Projeção'!C42*'Premissas'!$D$29 | E16: ='Projeção'!D42*'Premissas'!$D$29 | F16: ='Projeção'!E42*'Premissas'!$D$29 | G16: ='Projeção'!F42*'Premissas'!$D$29 | H16: ='Projeção'!G42*'Premissas'!$D$29
B17: Amortização líquida de dívida (se negativa a captação) | D17: =MAX(0,-'Projeção'!D32) | E17: =MAX(0,-'Projeção'!E32) | F17: =MAX(0,-'Projeção'!F32) | G17: =MAX(0,-'Projeção'!G32) | H17: =MAX(0,-'Projeção'!H32)
B18: Dividendos | D18: ='Projeção'!D34 | E18: ='Projeção'!E34 | F18: ='Projeção'!F34 | G18: ='Projeção'!G34 | H18: ='Projeção'!H34
B19: Total de saídas | D19: =SUM(D13:D18) | E19: =SUM(E13:E18) | F19: =SUM(F13:F18) | G19: =SUM(G13:G18) | H19: =SUM(H13:H18)
B20: Saldo
B21: Entradas - saídas | D21: =D11-D19 | E21: =E11-E19 | F21: =F11-F19 | G21: =G11-G19 | H21: =H11-H19
B22: Caixa no fim do ano | D22: ='Projeção'!D38 | E22: ='Projeção'!E38 | F22: ='Projeção'!F38 | G22: ='Projeção'!G38 | H22: ='Projeção'!H38
B23: Checagem: bate com a variação de caixa da projeção (zero) | D23: =ROUND(D21-'Projeção'!D35,3) | E23: =ROUND(E21-'Projeção'!E35,3) | F23: =ROUND(F21-'Projeção'!F35,3) | G23: =ROUND(G21-'Projeção'!G35,3) | H23: =ROUND(H21-'Projeção'!H35,3)
B26: Comparativo dos cenários (calculado pelo modelo) | D26: Pessimista | E26: Moderado | F26: Otimista
B27: Preço justo por ação | D27: 11.461837 | E27: 21.314042 | F27: 40.691134
B28: Valor da empresa (EV) | D28: 27108.638 | E28: 46450.297 | F28: 84491.029
B29: Valor do acionista | D29: 22501.655 | E29: 41843.314 | F29: 79884.046
B30: WACC | D30: 0.16090375 | E30: 0.14530375 | F30: 0.12970375
B31: Receita 2030E | D31: 69544.169 | E31: 80670.618 | F31: 88129.693
B32: Margem EBITDA 2030E | D32: 0.1613 | E32: 0.1971 | F32: 0.2506
B33: Caixa no fim de 2030E | D33: 11133.542 | E33: 12136.958 | F33: 16436.585
B34: Dívida líquida / EBITDA 2030E | D34: 0.27177321 | E34: 0.12862704 | F34: -0.10207846
B36: Preço justo na planilha viva, no cenário em uso | D36: ='DCF'!$D$30
B37: Diferença para o comparativo acima (zero sem ajuste manual) | D37: =IF(COUNT('Premissas'!$H$8:$H$10)=0,ROUND(D36-INDEX(D27:F27,'Premissas'!$D$5),2),"-")
